Workbook

Sheet BM01(NHAP HANG SILO)
A1: CÔNG TY CỔ PHẦN CHĂN NUÔI C.P VIỆT NAM
A2: Chi Nhánh Tại Bình Dương
A3: Phòng Sản Xuất
E4: BÁO CÁO NHẬP HÀNG VÀO SILO
A7: Ca:…………………… | M7: Ngày : ……..... /………...../……….……..
A8: STT | B8: Xe số | C8: Tên hàng | D8: Loại hàng | E8: Độ ẩm | F8: Từ line | G8: Đến bồn | H8: Khối lượng nhập (tấn) | I8: Thời gian chạy máy | K8: Tổng thời gian chạy | L8: Thời gian ngưng máy | N8: Tổng thời gian ngưng | O8: Lý do ngưng máy | P8: Khắc phục sửa chữa
I11: Bắt đầu | J11: Kết thúc | L11: Bắt đầu | M11: Kết thúc
A12: 1
A13: 2
A14: 3
A15: 4
A16: 5
A17: 6
A18: 7
A19: 8
A20: 9
A21: 10
A22: 11
A23: 12
... A33: 22
F34: T.Cộng (tấn) : | I34: Tổng cộng Total | L34: Tổng cộng Total
A35: BM01/QT-SX-01 Lần ban hành: 02 Ngày ban hành: 10/11/2011 | F35: Tấn / giờ :
G37: Người báo cáo : ……………………...…………. | M37: Người thẩm tra:……………………………………..

Sheet 1
A1: CÔNG TY CỔ PHẦN CHĂN NUÔI CP VIỆT NAM
A2: NHÀ MÁY : BÌNH DƯƠNG
A3: BỘ PHẬN / PHÒNG: KHO NGUYÊN LIỆU
A4: BÁO CÁO VẬN HÀNH VÀ KIỂM SOÁT QUÁ TRÌNH HẤP NGUYÊN LIỆU
Y5: Ngày:.……01…../….06….../……2026.…….
A6: Ca | B6: Nguyên liệu | C6: Từ bồn | D6: Đến bồn | E6: Sản lượng (tấn) | F6: Thời gian chạy | I6: Thời gian ngưng | M6: Lý do ngưng | Q6: KẾT QUẢ KIỂM TRA CHẤT LƯỢNG | Z6: Ampe máy hấp | AA6: % Feeder | AB6: Nhiệt độ hơi (°C) | AC6: Nhiệt độ máy | AG6: Điện sử dụng máy hấp | AJ6: Hơi nóng sử dụng | AM6: Điện sử dụng LINE | AP6: Điện sử dụng máy nghiền
F7: Bắt đầu | G7: Kết thúc | H7: Tổng cộng | I7: Bắt đầu | J7: Kết thúc | K7: Tổng cộng | M7: 1 | O7: 2 | Q7: Mẫu trước hấp | S7: Mẫu sau hấp | AC7: Conditioner | AD7: Extruder | AE7: Môi trường | AG7: Số đầu | AH7: Số cuối | AI7: KWh | AJ7: Số đầu | AK7: Số cuối | AL7: Kg hơi | AM7: Số đầu | AN7: Số cuối | AO7: KWh | AP7: Số đầu | AQ7: Số cuối | AR7: KWh
S8: Thời gian lấy mẫu | T8: Đậu nành | V8: Bắp
K9: 1 | L9: 2 | M9: Mã số | N9: Số lần | O9: Mã số | P9: Số lần | T9: Chỉ số PS | U9: Chỉ số Trypsin | V9: Chỉ số Hydro | W9: %M | X9: Nhiệt độ Cooler | Y9: Người kiểm tra
A10: 1 | H10: =HOUR(G10-F10)+MINUTE(G10-F10)/60 -> 0 | I10: 0.25 | J10: 0.5 | K10: =HOUR(J10-I10)+MINUTE(J10-I10)/60 -> 6 | M10: 153 | N10: 1 | Q10: Đặc điểm về cảm quang: | AI10: =IFERROR((AH10-AG10),"") -> 0 | AL10: =IFERROR((AK10-AJ10),"") -> 0 | AO10: =IFERROR((AN10-AM10),"") -> 0 | AR10: =IFERROR((AQ10-AP10),"") -> 0
A11: 1 | B11: FFS | C11: 4 | D11: 39 | E11: 10 | F11: 0.5 | G11: 0.58333333 | H11: =HOUR(G11-F11)+MINUTE(G11-F11)/60 -> 2 | K11: =HOUR(J11-I11)+MINUTE(J11-I11)/60 -> 0 | Q11: 1.Trong chuẩn | R11: v | S11: 0.54166667 | T11: 80.14 | U11: 9.13 | W11: 10.8 | X11: 33 | Y11: quyết | Z11: 112 | AA11: 65 | AB11: 100 | AC11: 101 | AD11: 133 | AE11: 33 | AG11: 635274 | AH11: 635394 | AI11: =IFERROR((AH11-AG11),"") -> 120 | AJ11: 18961 | AK11: 19859 | AL11: =IFERROR((AK11-AJ11),"") -> 898 | AM11: 956895 | AN11: 956962 | AO11: =IFERROR((AN11-AM11),"") -> 67 | AP11: 362979 | AQ11: 363111 | AR11: =IFERROR((AQ11-AP11),"") -> 132
H12: =HOUR(G12-F12)+MINUTE(G12-F12)/60 -> 0 | K12: =HOUR(J12-I12)+MINUTE(J12-I12)/60 -> 0 | Q12: 2.Ngoài chuẩn | S12: 0.58333333 | T12: 79.58 | U12: 9.71 | W12: 10.8 | X12: 33 | Y12: quyết | Z12: 113 | AA12: 65 | AB12: 100 | AC12: 102 | AD12: 133 | AE12: 33 | AI12: =IFERROR((AH12-AG12),"") -> 0 | AL12: =IFERROR((AK12-AJ12),"") -> 0 | AO12: =IFERROR((AN12-AM12),"") -> 0 | AR12: =IFERROR((AQ12-AP12),"") -> 0
H13: =HOUR(G13-F13)+MINUTE(G13-F13)/60 -> 0 | K13: =HOUR(J13-I13)+MINUTE(J13-I13)/60 -> 0 | Q13: 3.Loại Lưới : | R13: 2,5mm | AI13: =IFERROR((AH13-AG13),"") -> 0 | AL13: =IFERROR((AK13-AJ13),"") -> 0 | AO13: =IFERROR((AN13-AM13),"") -> 0 | AR13: =IFERROR((AQ13-AP13),"") -> 0
A14: 2 | B14: FFS | C14: 4 | D14: 39 | E14: 14 | F14: 0.58333333 | G14: 0.69791667 | H14: =HOUR(G14-F14)+MINUTE(G14-F14)/60 -> 2.75 | I14: 0.69791667 | J14: 0.91666667 | K14: =HOUR(J14-I14)+MINUTE(J14-I14)/60 -> 5.25 | M14: 153 | N14: 1 | Q14: 1.Trong chuẩn | R14: v | S14: 0.625 | T14: 78.54 | U14: 9.79 | W14: 10.9 | X14: 33 | Y14: quyết | Z14: 113 | AA14: 65 | AB14: 100 | AC14: 101 | AD14: 133 | AE14: 33 | AG14: 635394 | AH14: 635587 | AI14: =IFERROR((AH14-AG14),"") -> 193 | AJ14: 19859 | AK14: 21446 | AL14: =IFERROR((AK14-AJ14),"") -> 1587 | AM14: 956962 | AN14: 957047 | AO14: =IFERROR((AN14-AM14),"") -> 85 | AP14: 363111 | AQ14: 363338 | AR14: =IFERROR((AQ14-AP14),"") -> 227
H15: =HOUR(G15-F15)+MINUTE(G15-F15)/60 -> 0 | K15: =HOUR(J15-I15)+MINUTE(J15-I15)/60 -> 0 | Q15: 2.Ngoài chuẩn | S15: 0.66666667 | T15: 78.32 | U15: 9.37 | W15: 10.9 | X15: 33 | Y15: quyết | Z15: 109 | AA15: 65 | AB15: 100 | AC15: 101 | AD15: 133 | AE15: 33 | AI15: =IFERROR((AH15-AG15),"") -> 0 | AL15: =IFERROR((AK15-AJ15),"") -> 0 | AO15: =IFERROR((AN15-AM15),"") -> 0 | AR15: =IFERROR((AQ15-AP15),"") -> 0
H16: =HOUR(G16-F16)+MINUTE(G16-F16)/60 -> 0 | K16: =HOUR(J16-I16)+MINUTE(J16-I16)/60 -> 0 | Q16: 3.Loại Lưới : | R16: 2,5mm | AI16: =IFERROR((AH16-AG16),"") -> 0 | AL16: =IFERROR((AK16-AJ16),"") -> 0 | AO16: =IFERROR((AN16-AM16),"") -> 0 | AR16: =IFERROR((AQ16-AP16),"") -> 0
H17: =HOUR(G17-F17)+MINUTE(G17-F17)/60 -> 0 | K17: =HOUR(J17-I17)+MINUTE(J17-I17)/60 -> 0 | Q17: Đặc điểm về cảm quang: | AI17: =IFERROR((AH17-AG17),"") -> 0 | AL17: =IFERROR((AK17-AJ17),"") -> 0 | AO17: =IFERROR((AN17-AM17),"") -> 0 | AR17: =IFERROR((AQ17-AP17),"") -> 0
A18: 3 | B18: CORN | C18: 1 | D18: 30 | E18: 66 | F18: 0.91666667 | G18: 1.25 | H18: =HOUR(G18-F18)+MINUTE(G18-F18)/60 -> 8 | I18: 1.25 | J18: 1.25 | K18: =HOUR(J18-I18)+MINUTE(J18-I18)/60 -> 0 | Q18: 1.Trong chuẩn | R18: v | S18: 0.95833333 | V18: 40.21 | W18: 12.5 | X18: 33 | Y18: thanh | Z18: 121 | AA18: 70 | AB18: 100 | AC18: 101 | AD18: 120 | AE18: 32 | AG18: 39103 | AH18: 39728 | AI18: =IFERROR((AH18-AG18),"") -> 625 | AJ18: 9192302 | AK18: 9195440 | AL18: =IFERROR((AK18-AJ18),"") -> 3138 | AM18: 957047 | AN18: 957279 | AO18: =IFERROR((AN18-AM18),"") -> 232 | AP18: 363338 | AQ18: 363868 | AR18: =IFERROR((AQ18-AP18),"") -> 530
H19: =HOUR(G19-F19)+MINUTE(G19-F19)/60 -> 0 | K19: =HOUR(J19-I19)+MINUTE(J19-I19)/60 -> 0 | Q19: 2.Ngoài chuẩn | S19: 1 | V19: 40.12 | W19: 12.5 | X19: 33 | Y19: thanh | Z19: 115 | AA19: 70 | AB19: 100 | AC19: 101 | AD19: 118 | AE19: 32 | AI19: =IFERROR((AH19-AG19),"") -> 0 | AL19: =IFERROR((AK19-AJ19),"") -> 0 | AO19: =IFERROR((AN19-AM19),"") -> 0 | AR19: =IFERROR((AQ19-AP19),"") -> 0
H20: =HOUR(G20-F20)+MINUTE(G20-F20)/60 -> 0 | K20: =HOUR(J20-I20)+MINUTE(J20-I20)/60 -> 0 | Q20: 3.Loại Lưới : | R20: 3,0mm | S20: 1.0416667 | V20: 40.02 | W20: 12.5 | X20: 33 | Y20: thanh | Z20: 109 | AA20: 70 | AB20: 100 | AC20: 101 | AD20: 119 | AE20: 31 | AI20: =IFERROR((AH20-AG20),"") -> 0 | AL20: =IFERROR((AK20-AJ20),"") -> 0 | AO20: =IFERROR((AN20-AM20),"") -> 0 | AR20: =IFERROR((AQ20-AP20),"") -> 0
H21: =HOUR(G21-F21)+MINUTE(G21-F21)/60 -> 0 | K21: =HOUR(J21-I21)+MINUTE(J21-I21)/60 -> 0 | S21: 1.0833333 | V21: 40.015 | W21: 12.5 | X21: 34 | Y21: thanh | Z21: 112 | AA21: 70 | AB21: 100 | AC21: 102 | AD21: 118 | AE21: 30 | AI21: =IFERROR((AH21-AG21),"") -> 0 | AL21: =IFERROR((AK21-AJ21),"") -> 0 | AO21: =IFERROR((AN21-AM21),"") -> 0 | AR21: =IFERROR((AQ21-AP21),"") -> 0
H22: =HOUR(G22-F22)+MINUTE(G22-F22)/60 -> 0 | K22: =HOUR(J22-I22)+MINUTE(J22-I22)/60 -> 0 | S22: 1.125 | V22: 41.25 | W22: 12.5 | X22: 34 | Y22: thanh | Z22: 117 | AA22: 70 | AB22: 100 | AC22: 101 | AD22: 118 | AE22: 30 | AI22: =IFERROR((AH22-AG22),"") -> 0 | AL22: =IFERROR((AK22-AJ22),"") -> 0 | AO22: =IFERROR((AN22-AM22),"") -> 0 | AR22: =IFERROR((AQ22-AP22),"") -> 0
H23: =HOUR(G23-F23)+MINUTE(G23-F23)/60 -> 0 | K23: =HOUR(J23-I23)+MINUTE(J23-I23)/60 -> 0 | S23: 1.1666667 | V23: 40.31 | W23: 12.5 | X23: 33 | Y23: thanh | Z23: 116 | AA23: 70 | AB23: 100 | AC23: 100 | AD23: 118 | AE23: 30 | AI23: =IFERROR((AH23-AG23),"") -> 0 | AL23: =IFERROR((AK23-AJ23),"") -> 0 | AO23: =IFERROR((AN23-AM23),"") -> 0 | AR23: =IFERROR((AQ23-AP23),"") -> 0
H24: =HOUR(G24-F24)+MINUTE(G24-F24)/60 -> 0 | K24: =HOUR(J24-I24)+MINUTE(J24-I24)/60 -> 0 | S24: 1.2083333 | V24: 40.01 | W24: 12.5 | X24: 34 | Y24: thanh | Z24: 121 | AA24: 70 | AB24: 100 | AC24: 101 | AD24: 119 | AE24: 30 | AI24: =IFERROR((AH24-AG24),"") -> 0 | AL24: =IFERROR((AK24-AJ24),"") -> 0 | AO24: =IFERROR((AN24-AM24),"") -> 0 | AR24: =IFERROR((AQ24-AP24),"") -> 0
H25: =HOUR(G25-F25)+MINUTE(G25-F25)/60 -> 0 | K25: =HOUR(J25-I25)+MINUTE(J25-I25)/60 -> 0 | S25: 1.25 | V25: 40.41 | W25: 12.5 | X25: 33 | Y25: thanh | Z25: 123 | AA25: 70 | AB25: 100 | AC25: 101 | AD25: 120 | AE25: 30 | AI25: =IFERROR((AH25-AG25),"") -> 0 | AL25: =IFERROR((AK25-AJ25),"") -> 0 | AO25: =IFERROR((AN25-AM25),"") -> 0 | AR25: =IFERROR((AQ25-AP25),"") -> 0
H26: =HOUR(G26-F26)+MINUTE(G26-F26)/60 -> 0 | K26: =HOUR(J26-I26)+MINUTE(J26-I26)/60 -> 0 | AI26: =IFERROR((AH26-AG26),"") -> 0 | AL26: =IFERROR((AK26-AJ26),"") -> 0 | AO26: =IFERROR((AN26-AM26),"") -> 0 | AR26: =IFERROR((AQ26-AP26),"") -> 0
H27: =HOUR(G27-F27)+MINUTE(G27-F27)/60 -> 0 | K27: =HOUR(J27-I27)+MINUTE(J27-I27)/60 -> 0 | AI27: =IFERROR((AH27-AG27),"") -> 0 | AL27: =IFERROR((AK27-AJ27),"") -> 0 | AO27: =IFERROR((AN27-AM27),"") -> 0 | AR27: =IFERROR((AQ27-AP27),"") -> 0
H28: =HOUR(G28-F28)+MINUTE(G28-F28)/60 -> 0 | K28: =HOUR(J28-I28)+MINUTE(J28-I28)/60 -> 0 | AI28: =IFERROR((AH28-AG28),"") -> 0 | AL28: =IFERROR((AK28-AJ28),"") -> 0 | AO28: =IFERROR((AN28-AM28),"") -> 0 | AR28: =IFERROR((AQ28-AP28),"") -> 0
H29: =HOUR(G29-F29)+MINUTE(G29-F29)/60 -> 0 | K29: =HOUR(J29-I29)+MINUTE(J29-I29)/60 -> 0 | AI29: =IFERROR((AH29-AG29),"") -> 0 | AL29: =IFERROR((AK29-AJ29),"") -> 0 | AO29: =IFERROR((AN29-AM29),"") -> 0 | AR29: =IFERROR((AQ29-AP29),"") -> 0
H30: =HOUR(G30-F30)+MINUTE(G30-F30)/60 -> 0 | K30: =HOUR(J30-I30)+MINUTE(J30-I30)/60 -> 0 | AI30: =IFERROR((AH30-AG30),"") -> 0 | AL30: =IFERROR((AK30-AJ30),"") -> 0 | AO30: =IFERROR((AN30-AM30),"") -> 0 | AR30: =IFERROR((AQ30-AP30),"") -> 0
H31: =HOUR(G31-F31)+MINUTE(G31-F31)/60 -> 0 | K31: =HOUR(J31-I31)+MINUTE(J31-I31)/60 -> 0 | AI31: =IFERROR((AH31-AG31),"") -> 0 | AL31: =IFERROR((AK31-AJ31),"") -> 0 | AO31: =IFERROR((AN31-AM31),"") -> 0 | AR31: =IFERROR((AQ31-AP31),"") -> 0
H32: =HOUR(G32-F32)+MINUTE(G32-F32)/60 -> 0 | K32: =HOUR(J32-I32)+MINUTE(J32-I32)/60 -> 0 | AI32: =IFERROR((AH32-AG32),"") -> 0 | AL32: =IFERROR((AK32-AJ32),"") -> 0 | AO32: =IFERROR((AN32-AM32),"") -> 0 | AR32: =IFERROR((AQ32-AP32),"") -> 0
H33: =HOUR(G33-F33)+MINUTE(G33-F33)/60 -> 0 | K33: =HOUR(J33-I33)+MINUTE(J33-I33)/60 -> 0 | AI33: =IFERROR((AH33-AG33),"") -> 0 | AL33: =IFERROR((AK33-AJ33),"") -> 0 | AO33: =IFERROR((AN33-AM33),"") -> 0 | AR33: =IFERROR((AQ33-AP33),"") -> 0
H34: =HOUR(G34-F34)+MINUTE(G34-F34)/60 -> 0 | K34: =HOUR(J34-I34)+MINUTE(J34-I34)/60 -> 0 | AI34: =IFERROR((AH34-AG34),"") -> 0 | AL34: =IFERROR((AK34-AJ34),"") -> 0 | AO34: =IFERROR((AN34-AM34),"") -> 0 | AR34: =IFERROR((AQ34-AP34),"") -> 0
H35: =HOUR(G35-F35)+MINUTE(G35-F35)/60 -> 0 | K35: =HOUR(J35-I35)+MINUTE(J35-I35)/60 -> 0 | AI35: =IFERROR((AH35-AG35),"") -> 0 | AL35: =IFERROR((AK35-AJ35),"") -> 0 | AO35: =IFERROR((AN35-AM35),"") -> 0 | AR35: =IFERROR((AQ35-AP35),"") -> 0
H36: =HOUR(G36-F36)+MINUTE(G36-F36)/60 -> 0 | K36: =HOUR(J36-I36)+MINUTE(J36-I36)/60 -> 0 | AI36: =IFERROR((AH36-AG36),"") -> 0 | AL36: =IFERROR((AK36-AJ36),"") -> 0 | AO36: =IFERROR((AN36-AM36),"") -> 0 | AR36: =IFERROR((AQ36-AP36),"") -> 0
H37: =HOUR(G37-F37)+MINUTE(G37-F37)/60 -> 0 | K37: =HOUR(J37-I37)+MINUTE(J37-I37)/60 -> 0 | AI37: =IFERROR((AH37-AG37),"") -> 0 | AL37: =IFERROR((AK37-AJ37),"") -> 0 | AO37: =IFERROR((AN37-AM37),"") -> 0 | AR37: =IFERROR((AQ37-AP37),"") -> 0
... H44: =HOUR(G44-F44)+MINUTE(G44-F44)/60 -> 0 | K44: =HOUR(J44-I44)+MINUTE(J44-I44)/60 -> 0 | AI44: =IFERROR((AH44-AG44),"") -> 0 | AL44: =IFERROR((AK44-AJ44),"") -> 0 | AO44: =IFERROR((AN44-AM44),"") -> 0 | AR44: =IFERROR((AQ44-AP44),"") -> 0
A46: QT-NL-01/BM15…………
A47: Lần ban hành: …06…………
...

Sheet 2
A1: CÔNG TY CỔ PHẦN CHĂN NUÔI C.P VIỆT NAM
A2: Chi Nhánh Tại Bình Dương
A3: Phòng Kho Nguyên Liệu
A4: BÁO CÁO VẬN HÀNH VÀ KIỂM SOÁT QUÁ TRÌNH HẤP NGUYÊN LIỆU
Z5: Ngày:.…..02.…../…06..../…2026….…….
A6: Ca | B6: Nguyên liệu | C6: Từ bồn | D6: Đến bồn | E6: Sản lượng (tấn) | F6: Thời gian chạy | I6: Thời gian ngưng | M6: Lý do ngưng | Q6: KẾT QUẢ KIỂM TRA CHẤT LƯỢNG | Z6: Ampe máy hấp | AA6: % Feeder | AB6: Nhiệt độ hơi (°C) | AC6: Nhiệt độ máy | AG6: Điện sử dụng máy hấp | AJ6: Hơi nóng sử dụng | AM6: Điện sử dụng LINE | AP6: Điện sử dụng máy nghiền
F7: Bắt đầu | G7: Kết thúc | H7: Tổng cộng | I7: Bắt đầu | J7: Kết thúc | K7: Tổng cộng | M7: 1 | O7: 2 | Q7: Mẫu trước hấp | S7: Mẫu sau hấp | AC7: Conditioner | AD7: Extruder | AE7: Môi trường | AG7: Số đầu | AH7: Số cuối | AI7: KWh | AJ7: Số đầu | AK7: Số cuối | AL7: Kg hơi | AM7: Số đầu | AN7: Số cuối | AO7: KWh | AP7: Số đầu | AQ7: Số cuối | AR7: KWh
K8: 1 | L8: 2 | M8: Mã số | N8: Số lần | O8: Mã số | P8: Số lần | S8: Thời gian lấy mẫu | T8: Đậu nành | V8: Bắp | W8: %M | X8: Nhiệt độ Cooler | Y8: Người kiểm tra
T9: Chỉ số PS | U9: Chỉ số Trypsin | V9: Chỉ số Hydro
A10: 1 | B10: CORN | C10: 1 | D10: 30 | E10: 25 | F10: 0.25 | G10: 0.375 | H10: =HOUR(G10-F10)+MINUTE(G10-F10)/60 -> 3 | I10: 0.375 | J10: 0.47916667 | K10: =HOUR(J10-I10)+MINUTE(J10-I10)/60 -> 2.5 | M10: 153 | N10: 1 | Q10: Đặc điểm về cảm quang: | S10: 0.29166667 | V10: 40.21 | W10: 12.5 | X10: 33 | Y10: quyết | Z10: 121 | AA10: 72 | AB10: 100 | AC10: 101 | AD10: 120 | AE10: 32 | AG10: 39728 | AH10: 39991 | AI10: =IFERROR((AH10-AG10),"") -> 263 | AJ10: 9195440 | AK10: 9197728 | AL10: =IFERROR((AK10-AJ10),"") -> 2288 | AM10: 957279 | AN10: 957366 | AO10: =IFERROR((AN10-AM10),"") -> 87 | AP10: 363868 | AQ10: 364081 | AR10: =IFERROR((AQ10-AP10),"") -> 213
H11: =HOUR(G11-F11)+MINUTE(G11-F11)/60 -> 0 | K11: =HOUR(J11-I11)+MINUTE(J11-I11)/60 -> 0 | Q11: 1.Trong chuẩn | R11: v | S11: 0.33333333 | V11: 40.52 | W11: 12.5 | X11: 33 | Y11: quyết | Z11: 115 | AA11: 72 | AB11: 100 | AC11: 101 | AD11: 118 | AE11: 32 | AI11: =IFERROR((AH11-AG11),"") -> 0 | AL11: =IFERROR((AK11-AJ11),"") -> 0 | AO11: =IFERROR((AN11-AM11),"") -> 0 | AR11: =IFERROR((AQ11-AP11),"") -> 0
H12: =HOUR(G12-F12)+MINUTE(G12-F12)/60 -> 0 | K12: =HOUR(J12-I12)+MINUTE(J12-I12)/60 -> 0 | Q12: 2.Ngoài chuẩn | AI12: =IFERROR((AH12-AG12),"") -> 0 | AL12: =IFERROR((AK12-AJ12),"") -> 0 | AO12: =IFERROR((AN12-AM12),"") -> 0 | AR12: =IFERROR((AQ12-AP12),"") -> 0
H13: =HOUR(G13-F13)+MINUTE(G13-F13)/60 -> 0 | K13: =HOUR(J13-I13)+MINUTE(J13-I13)/60 -> 0 | Q13: 3.Loại Lưới : | R13: 3,0 mm | AI13: =IFERROR((AH13-AG13),"") -> 0 | AL13: =IFERROR((AK13-AJ13),"") -> 0 | AO13: =IFERROR((AN13-AM13),"") -> 0 | AR13: =IFERROR((AQ13-AP13),"") -> 0
A14: 1 | B14: FFS | C14: 4 | D14: 39 | E14: 12 | F14: 0.47916667 | G14: 0.58333333 | H14: =HOUR(G14-F14)+MINUTE(G14-F14)/60 -> 2.5 | K14: =HOUR(J14-I14)+MINUTE(J14-I14)/60 -> 0 | Q14: 1.Trong chuẩn | R14: v | S14: 0.5 | T14: 79.55 | U14: 9.74 | W14: 10.9 | X14: 33 | Y14: quyết | Z14: 113 | AA14: 65 | AB14: 100 | AC14: 101 | AD14: 133 | AE14: 33 | AG14: 635587 | AH14: 635734 | AI14: =IFERROR((AH14-AG14),"") -> 147 | AJ14: 21446 | AK14: 22444 | AL14: =IFERROR((AK14-AJ14),"") -> 998 | AM14: 957366 | AN14: 957442 | AO14: =IFERROR((AN14-AM14),"") -> 76 | AP14: 364081 | AQ14: 364215 | AR14: =IFERROR((AQ14-AP14),"") -> 134
H15: =HOUR(G15-F15)+MINUTE(G15-F15)/60 -> 0 | K15: =HOUR(J15-I15)+MINUTE(J15-I15)/60 -> 0 | Q15: 2.Ngoài chuẩn | S15: 0.54166667 | T15: 80.14 | U15: 9.77 | W15: 10.9 | X15: 33 | Y15: quyết | Z15: 109 | AA15: 65 | AB15: 100 | AC15: 101 | AD15: 133 | AE15: 33 | AI15: =IFERROR((AH15-AG15),"") -> 0 | AL15: =IFERROR((AK15-AJ15),"") -> 0 | AO15: =IFERROR((AN15-AM15),"") -> 0 | AR15: =IFERROR((AQ15-AP15),"") -> 0
H16: =HOUR(G16-F16)+MINUTE(G16-F16)/60 -> 0 | K16: =HOUR(J16-I16)+MINUTE(J16-I16)/60 -> 0 | Q16: 3.Loại Lưới : | R16: 2,5mm | AI16: =IFERROR((AH16-AG16),"") -> 0 | AL16: =IFERROR((AK16-AJ16),"") -> 0 | AO16: =IFERROR((AN16-AM16),"") -> 0 | AR16: =IFERROR((AQ16-AP16),"") -> 0
A17: 2 | B17: FFS | C17: 4 | D17: 39 | E17: 13 | F17: 0.58333333 | G17: 0.6875 | H17: =HOUR(G17-F17)+MINUTE(G17-F17)/60 -> 2.5 | I17: 0.6875 | J17: 0.91666667 | K17: =HOUR(J17-I17)+MINUTE(J17-I17)/60 -> 5.5 | M17: 153 | N17: 1 | Q17: 1.Trong chuẩn | R17: v | S17: 0.625 | T17: 79.58 | U17: 9.74 | W17: 10.9 | X17: 33 | Y17: quyết | Z17: 113 | AA17: 65 | AB17: 100 | AC17: 101 | AD17: 133 | AE17: 33 | AG17: 635734 | AH17: 635886 | AI17: =IFERROR((AH17-AG17),"") -> 152 | AJ17: 22444 | AK17: 23620 | AL17: =IFERROR((AK17-AJ17),"") -> 1176 | AM17: 957442 | AN17: 957511 | AO17: =IFERROR((AN17-AM17),"") -> 69 | AP17: 364215 | AQ17: 364387 | AR17: =IFERROR((AQ17-AP17),"") -> 172
H18: =HOUR(G18-F18)+MINUTE(G18-F18)/60 -> 0 | K18: =HOUR(J18-I18)+MINUTE(J18-I18)/60 -> 0 | Q18: 2.Ngoài chuẩn | S18: 0.66666667 | T18: 80.14 | U18: 10.11 | W18: 10.9 | X18: 33 | Y18: quyết | Z18: 109 | AA18: 65 | AB18: 100 | AC18: 101 | AD18: 133 | AE18: 33 | AI18: =IFERROR((AH18-AG18),"") -> 0 | AL18: =IFERROR((AK18-AJ18),"") -> 0 | AO18: =IFERROR((AN18-AM18),"") -> 0 | AR18: =IFERROR((AQ18-AP18),"") -> 0
H19: =HOUR(G19-F19)+MINUTE(G19-F19)/60 -> 0 | K19: =HOUR(J19-I19)+MINUTE(J19-I19)/60 -> 0 | Q19: 3.Loại Lưới : | R19: 2,5mm | AI19: =IFERROR((AH19-AG19),"") -> 0 | AL19: =IFERROR((AK19-AJ19),"") -> 0 | AO19: =IFERROR((AN19-AM19),"") -> 0 | AR19: =IFERROR((AQ19-AP19),"") -> 0
H20: =HOUR(G20-F20)+MINUTE(G20-F20)/60 -> 0 | K20: =HOUR(J20-I20)+MINUTE(J20-I20)/60 -> 0 | Q20: Đặc điểm về cảm quang: | AI20: =IFERROR((AH20-AG20),"") -> 0 | AL20: =IFERROR((AK20-AJ20),"") -> 0 | AO20: =IFERROR((AN20-AM20),"") -> 0 | AR20: =IFERROR((AQ20-AP20),"") -> 0
A21: 3 | B21: CORN | C21: 1 | D21: 30 | H21: =HOUR(G21-F21)+MINUTE(G21-F21)/60 -> 0 | I21: 0.91666667 | J21: 1.0416667 | K21: =HOUR(J21-I21)+MINUTE(J21-I21)/60 -> 3 | M21: 502 | N21: 1 | Q21: 1.Trong chuẩn | R21: v | AI21: =IFERROR((AH21-AG21),"") -> 0 | AL21: =IFERROR((AK21-AJ21),"") -> 0 | AO21: =IFERROR((AN21-AM21),"") -> 0 | AR21: =IFERROR((AQ21-AP21),"") -> 0
A22: 3 | B22: FFS | C22: 4 | D22: 39 | E22: 25 | F22: 1.0416667 | G22: 1.25 | H22: =HOUR(G22-F22)+MINUTE(G22-F22)/60 -> 5 | I22: 1.25 | J22: 1.25 | K22: =HOUR(J22-I22)+MINUTE(J22-I22)/60 -> 0 | Q22: 2.Ngoài chuẩn | S22: 1.0833333 | T22: 78.36 | U22: 9.52 | X22: 33 | Y22: thanh | Z22: 118 | AA22: 65 | AB22: 100 | AC22: 101 | AD22: 133 | AE22: 32 | AG22: 635886 | AH22: 636255 | AI22: =IFERROR((AH22-AG22),"") -> 369 | AJ22: 23625 | AK22: 25891 | AL22: =IFERROR((AK22-AJ22),"") -> 2266 | AM22: 957511 | AN22: 957668 | AO22: =IFERROR((AN22-AM22),"") -> 157 | AP22: 364387 | AQ22: 364806 | AR22: =IFERROR((AQ22-AP22),"") -> 419
H23: =HOUR(G23-F23)+MINUTE(G23-F23)/60 -> 0 | K23: =HOUR(J23-I23)+MINUTE(J23-I23)/60 -> 0 | Q23: 3.Loại Lưới : | R23: 2,0 mm | S23: 1.125 | T23: 79.58 | U23: 9.34 | X23: 33 | Y23: thanh | Z23: 120 | AA23: 60 | AB23: 100 | AC23: 102 | AD23: 134 | AE23: 32 | AI23: =IFERROR((AH23-AG23),"") -> 0 | AL23: =IFERROR((AK23-AJ23),"") -> 0 | AO23: =IFERROR((AN23-AM23),"") -> 0 | AR23: =IFERROR((AQ23-AP23),"") -> 0
H24: =HOUR(G24-F24)+MINUTE(G24-F24)/60 -> 0 | K24: =HOUR(J24-I24)+MINUTE(J24-I24)/60 -> 0 | S24: 1.1666667 | T24: 79.26 | U24: 9.78 | X24: 32 | Y24: thanh | Z24: 121 | AA24: 55 | AB24: 100 | AC24: 102 | AD24: 133 | AE24: 32 | AI24: =IFERROR((AH24-AG24),"") -> 0 | AL24: =IFERROR((AK24-AJ24),"") -> 0 | AO24: =IFERROR((AN24-AM24),"") -> 0 | AR24: =IFERROR((AQ24-AP24),"") -> 0
H25: =HOUR(G25-F25)+MINUTE(G25-F25)/60 -> 0 | K25: =HOUR(J25-I25)+MINUTE(J25-I25)/60 -> 0 | S25: 1.2083333 | T25: 80.12 | U25: 9.63 | X25: 33 | Y25: thanh | Z25: 123 | AA25: 55 | AB25: 100 | AC25: 102 | AD25: 133 | AE25: 31 | AI25: =IFERROR((AH25-AG25),"") -> 0 | AL25: =IFERROR((AK25-AJ25),"") -> 0 | AO25: =IFERROR((AN25-AM25),"") -> 0 | AR25: =IFERROR((AQ25-AP25),"") -> 0
H26: =HOUR(G26-F26)+MINUTE(G26-F26)/60 -> 0 | K26: =HOUR(J26-I26)+MINUTE(J26-I26)/60 -> 0 | S26: 1.25 | T26: 80.24 | U26: 9.56 | X26: 33 | Y26: thanh | Z26: 122 | AA26: 55 | AB26: 100 | AC26: 101 | AD26: 133 | AE26: 31 | AI26: =IFERROR((AH26-AG26),"") -> 0 | AL26: =IFERROR((AK26-AJ26),"") -> 0 | AO26: =IFERROR((AN26-AM26),"") -> 0 | AR26: =IFERROR((AQ26-AP26),"") -> 0
H27: =HOUR(G27-F27)+MINUTE(G27-F27)/60 -> 0 | K27: =HOUR(J27-I27)+MINUTE(J27-I27)/60 -> 0 | AI27: =IFERROR((AH27-AG27),"") -> 0 | AL27: =IFERROR((AK27-AJ27),"") -> 0 | AO27: =IFERROR((AN27-AM27),"") -> 0 | AR27: =IFERROR((AQ27-AP27),"") -> 0
H28: =HOUR(G28-F28)+MINUTE(G28-F28)/60 -> 0 | K28: =HOUR(J28-I28)+MINUTE(J28-I28)/60 -> 0 | AI28: =IFERROR((AH28-AG28),"") -> 0 | AL28: =IFERROR((AK28-AJ28),"") -> 0 | AO28: =IFERROR((AN28-AM28),"") -> 0 | AR28: =IFERROR((AQ28-AP28),"") -> 0
H29: =HOUR(G29-F29)+MINUTE(G29-F29)/60 -> 0 | K29: =HOUR(J29-I29)+MINUTE(J29-I29)/60 -> 0 | AI29: =IFERROR((AH29-AG29),"") -> 0 | AL29: =IFERROR((AK29-AJ29),"") -> 0 | AO29: =IFERROR((AN29-AM29),"") -> 0 | AR29: =IFERROR((AQ29-AP29),"") -> 0
H30: =HOUR(G30-F30)+MINUTE(G30-F30)/60 -> 0 | K30: =HOUR(J30-I30)+MINUTE(J30-I30)/60 -> 0 | AI30: =IFERROR((AH30-AG30),"") -> 0 | AL30: =IFERROR((AK30-AJ30),"") -> 0 | AO30: =IFERROR((AN30-AM30),"") -> 0 | AR30: =IFERROR((AQ30-AP30),"") -> 0
H31: =HOUR(G31-F31)+MINUTE(G31-F31)/60 -> 0 | K31: =HOUR(J31-I31)+MINUTE(J31-I31)/60 -> 0 | AI31: =IFERROR((AH31-AG31),"") -> 0 | AL31: =IFERROR((AK31-AJ31),"") -> 0 | AO31: =IFERROR((AN31-AM31),"") -> 0 | AR31: =IFERROR((AQ31-AP31),"") -> 0
H32: =HOUR(G32-F32)+MINUTE(G32-F32)/60 -> 0 | K32: =HOUR(J32-I32)+MINUTE(J32-I32)/60 -> 0 | AI32: =IFERROR((AH32-AG32),"") -> 0 | AL32: =IFERROR((AK32-AJ32),"") -> 0 | AO32: =IFERROR((AN32-AM32),"") -> 0 | AR32: =IFERROR((AQ32-AP32),"") -> 0
H33: =HOUR(G33-F33)+MINUTE(G33-F33)/60 -> 0 | K33: =HOUR(J33-I33)+MINUTE(J33-I33)/60 -> 0 | AI33: =IFERROR((AH33-AG33),"") -> 0 | AL33: =IFERROR((AK33-AJ33),"") -> 0 | AO33: =IFERROR((AN33-AM33),"") -> 0 | AR33: =IFERROR((AQ33-AP33),"") -> 0
H34: =HOUR(G34-F34)+MINUTE(G34-F34)/60 -> 0 | K34: =HOUR(J34-I34)+MINUTE(J34-I34)/60 -> 0 | AI34: =IFERROR((AH34-AG34),"") -> 0 | AL34: =IFERROR((AK34-AJ34),"") -> 0 | AO34: =IFERROR((AN34-AM34),"") -> 0 | AR34: =IFERROR((AQ34-AP34),"") -> 0
H35: =HOUR(G35-F35)+MINUTE(G35-F35)/60 -> 0 | K35: =HOUR(J35-I35)+MINUTE(J35-I35)/60 -> 0 | AI35: =IFERROR((AH35-AG35),"") -> 0 | AL35: =IFERROR((AK35-AJ35),"") -> 0 | AO35: =IFERROR((AN35-AM35),"") -> 0 | AR35: =IFERROR((AQ35-AP35),"") -> 0
H36: =HOUR(G36-F36)+MINUTE(G36-F36)/60 -> 0 | K36: =HOUR(J36-I36)+MINUTE(J36-I36)/60 -> 0 | AI36: =IFERROR((AH36-AG36),"") -> 0 | AL36: =IFERROR((AK36-AJ36),"") -> 0 | AO36: =IFERROR((AN36-AM36),"") -> 0 | AR36: =IFERROR((AQ36-AP36),"") -> 0
H37: =HOUR(G37-F37)+MINUTE(G37-F37)/60 -> 0 | K37: =HOUR(J37-I37)+MINUTE(J37-I37)/60 -> 0 | AI37: =IFERROR((AH37-AG37),"") -> 0 | AL37: =IFERROR((AK37-AJ37),"") -> 0 | AO37: =IFERROR((AN37-AM37),"") -> 0 | AR37: =IFERROR((AQ37-AP37),"") -> 0
H38: =HOUR(G38-F38)+MINUTE(G38-F38)/60 -> 0 | K38: =HOUR(J38-I38)+MINUTE(J38-I38)/60 -> 0 | AI38: =IFERROR((AH38-AG38),"") -> 0 | AL38: =IFERROR((AK38-AJ38),"") -> 0 | AO38: =IFERROR((AN38-AM38),"") -> 0 | AR38: =IFERROR((AQ38-AP38),"") -> 0
... H44: =HOUR(G44-F44)+MINUTE(G44-F44)/60 -> 0 | K44: =HOUR(J44-I44)+MINUTE(J44-I44)/60 -> 0 | AI44: =IFERROR((AH44-AG44),"") -> 0 | AL44: =IFERROR((AK44-AJ44),"") -> 0 | AO44: =IFERROR((AN44-AM44),"") -> 0 | AR44: =IFERROR((AQ44-AP44),"") -> 0
A46: QT-NL-01/BM15…………
...

Sheet 3
A1: CÔNG TY CỔ PHẦN CHĂN NUÔI C.P VIỆT NAM
A2: Chi Nhánh Tại Bình Dương
A3: Phòng Kho Nguyên Liệu
A4: BÁO CÁO VẬN HÀNH VÀ KIỂM SOÁT QUÁ TRÌNH HẤP NGUYÊN LIỆU
Z5: Ngày:.…03…../.…06…/...2026.…….
A6: Ca | B6: Nguyên liệu | C6: Từ bồn | D6: Đến bồn | E6: Sản lượng (tấn) | F6: Thời gian chạy | I6: Thời gian ngưng | M6: Lý do ngưng | Q6: KẾT QUẢ KIỂM TRA CHẤT LƯỢNG | Z6: Ampe máy hấp | AA6: % Feeder | AB6: Nhiệt độ hơi (°C) | AC6: Nhiệt độ máy | AG6: Điện sử dụng máy hấp | AJ6: Hơi nóng sử dụng | AM6: Điện sử dụng LINE | AP6: Điện sử dụng máy nghiền
F7: Bắt đầu | G7: Kết thúc | H7: Tổng cộng | I7: Bắt đầu | J7: Kết thúc | K7: Tổng cộng | M7: 1 | O7: 2 | Q7: Mẫu trước hấp | S7: Mẫu sau hấp | AC7: Conditioner | AD7: Extruder | AE7: Môi trường | AG7: Số đầu | AH7: Số cuối | AI7: KWh | AJ7: Số đầu | AK7: Số cuối | AL7: Kg hơi | AM7: Số đầu | AN7: Số cuối | AO7: KWh | AP7: Số đầu | AQ7: Số cuối | AR7: KWh
K8: 1 | L8: 2 | M8: Mã số | N8: Số lần | O8: Mã số | P8: Số lần | S8: Thời gian lấy mẫu | T8: Đậu nành | V8: Bắp | W8: %M | X8: Nhiệt độ Cooler | Y8: Người kiểm tra
T9: Chỉ số PS | U9: Chỉ số Trypsin | V9: Chỉ số Hydro
A10: 1 | B10: FFS | C10: 4 | D10: 39 | E10: 24 | F10: 0.25 | G10: 0.4375 | H10: =HOUR(G10-F10)+MINUTE(G10-F10)/60 -> 4.5 | I10: 0.4375 | J10: 0.58333333 | K10: =HOUR(J10-I10)+MINUTE(J10-I10)/60 -> 3.5 | M10: 153 | N10: 1 | Q10: Đặc điểm về cảm quang: | S10: 0.29166667 | T10: 78.36 | U10: 9.52 | X10: 33 | Y10: quyết | Z10: 118 | AA10: 60 | AB10: 100 | AC10: 101 | AD10: 133 | AE10: 32 | AG10: 636255 | AH10: 636511 | AI10: =IFERROR((AH10-AG10),"") -> 256 | AJ10: 25891 | AK10: 28088 | AL10: =IFERROR((AK10-AJ10),"") -> 2197 | AM10: 957668 | AN10: 957785 | AO10: =IFERROR((AN10-AM10),"") -> 117 | AP10: 364806 | AQ10: 365169 | AR10: =IFERROR((AQ10-AP10),"") -> 363
H11: =HOUR(G11-F11)+MINUTE(G11-F11)/60 -> 0 | K11: =HOUR(J11-I11)+MINUTE(J11-I11)/60 -> 0 | Q11: 1.Trong chuẩn | R11: v | S11: 0.33333333 | T11: 79.58 | U11: 9.34 | X11: 33 | Y11: quyết | Z11: 120 | AA11: 60 | AB11: 100 | AC11: 102 | AD11: 134 | AE11: 32 | AI11: =IFERROR((AH11-AG11),"") -> 0 | AL11: =IFERROR((AK11-AJ11),"") -> 0 | AO11: =IFERROR((AN11-AM11),"") -> 0 | AR11: =IFERROR((AQ11-AP11),"") -> 0
H12: =HOUR(G12-F12)+MINUTE(G12-F12)/60 -> 0 | K12: =HOUR(J12-I12)+MINUTE(J12-I12)/60 -> 0 | Q12: 2.Ngoài chuẩn | AI12: =IFERROR((AH12-AG12),"") -> 0 | AL12: =IFERROR((AK12-AJ12),"") -> 0 | AO12: =IFERROR((AN12-AM12),"") -> 0 | AR12: =IFERROR((AQ12-AP12),"") -> 0
H13: =HOUR(G13-F13)+MINUTE(G13-F13)/60 -> 0 | K13: =HOUR(J13-I13)+MINUTE(J13-I13)/60 -> 0 | Q13: 3.Loại Lưới : | R13: 2,5mm | AI13: =IFERROR((AH13-AG13),"") -> 0 | AL13: =IFERROR((AK13-AJ13),"") -> 0 | AO13: =IFERROR((AN13-AM13),"") -> 0 | AR13: =IFERROR((AQ13-AP13),"") -> 0
A14: 2 | H14: =HOUR(G14-F14)+MINUTE(G14-F14)/60 -> 0 | I14: 0.58333333 | J14: 0.60416667 | K14: =HOUR(J14-I14)+MINUTE(J14-I14)/60 -> 0.5 | M14: 153 | N14: 1 | AI14: =IFERROR((AH14-AG14),"") -> 0 | AL14: =IFERROR((AK14-AJ14),"") -> 0 | AO14: =IFERROR((AN14-AM14),"") -> 0 | AR14: =IFERROR((AQ14-AP14),"") -> 0
A15: 2 | B15: FFS | C15: 4 | D15: 39 | E15: 11 | F15: 0.60416667 | G15: 0.6875 | H15: =HOUR(G15-F15)+MINUTE(G15-F15)/60 -> 2 | I15: 0.6875 | J15: 0.91666667 | K15: =HOUR(J15-I15)+MINUTE(J15-I15)/60 -> 5.5 | M15: 153 | N15: 1 | S15: 0.625 | T15: 79.44 | U15: 9.78 | W15: 10.9 | X15: 33 | Y15: quyết | Z15: 113 | AA15: 65 | AB15: 100 | AC15: 101 | AD15: 133 | AE15: 33 | AG15: 636511 | AH15: 636644 | AI15: =IFERROR((AH15-AG15),"") -> 133 | AJ15: 28088 | AK15: 28852 | AL15: =IFERROR((AK15-AJ15),"") -> 764 | AM15: 957785 | AN15: 957846 | AO15: =IFERROR((AN15-AM15),"") -> 61 | AP15: 365169 | AQ15: 365321 | AR15: =IFERROR((AQ15-AP15),"") -> 152
H16: =HOUR(G16-F16)+MINUTE(G16-F16)/60 -> 0 | K16: =HOUR(J16-I16)+MINUTE(J16-I16)/60 -> 0 | S16: 0.66666667 | T16: 79.55 | U16: 9.58 | W16: 10.9 | X16: 33 | Y16: quyết | Z16: 109 | AA16: 65 | AB16: 100 | AC16: 101 | AD16: 133 | AE16: 33 | AI16: =IFERROR((AH16-AG16),"") -> 0 | AL16: =IFERROR((AK16-AJ16),"") -> 0 | AO16: =IFERROR((AN16-AM16),"") -> 0 | AR16: =IFERROR((AQ16-AP16),"") -> 0
H17: =HOUR(G17-F17)+MINUTE(G17-F17)/60 -> 0 | K17: =HOUR(J17-I17)+MINUTE(J17-I17)/60 -> 0 | Q17: Đặc điểm về cảm quang: | AI17: =IFERROR((AH17-AG17),"") -> 0 | AL17: =IFERROR((AK17-AJ17),"") -> 0 | AO17: =IFERROR((AN17-AM17),"") -> 0 | AR17: =IFERROR((AQ17-AP17),"") -> 0
A18: 3 | B18: CORN | C18: 1 | D18: 30 | E18: 66 | F18: 0.91666667 | G18: 1.25 | H18: =HOUR(G18-F18)+MINUTE(G18-F18)/60 -> 8 | I18: 1.25 | J18: 1.25 | K18: =HOUR(J18-I18)+MINUTE(J18-I18)/60 -> 0 | Q18: 1.Trong chuẩn | R18: v | S18: 0.95833333 | V18: 40.12 | W18: 12.5 | X18: 33 | Y18: thanh | Z18: 130 | AA18: 60 | AB18: 100 | AC18: 101 | AD18: 118 | AE18: 31 | AG18: 39991 | AH18: 40689 | AI18: =IFERROR((AH18-AG18),"") -> 698 | AJ18: 9203633 | AK18: 9203648 | AL18: =IFERROR((AK18-AJ18),"") -> 15 | AM18: 957846 | AN18: 958070 | AO18: =IFERROR((AN18-AM18),"") -> 224 | AP18: 365321 | AQ18: 365790 | AR18: =IFERROR((AQ18-AP18),"") -> 469
H19: =HOUR(G19-F19)+MINUTE(G19-F19)/60 -> 0 | K19: =HOUR(J19-I19)+MINUTE(J19-I19)/60 -> 0 | Q19: 2.Ngoài chuẩn | S19: 1 | V19: 40.21 | W19: 12.5 | X19: 34 | Y19: thanh | Z19: 133 | AA19: 57 | AB19: 100 | AC19: 102 | AD19: 118 | AE19: 30 | AI19: =IFERROR((AH19-AG19),"") -> 0 | AL19: =IFERROR((AK19-AJ19),"") -> 0 | AO19: =IFERROR((AN19-AM19),"") -> 0 | AR19: =IFERROR((AQ19-AP19),"") -> 0
H20: =HOUR(G20-F20)+MINUTE(G20-F20)/60 -> 0 | K20: =HOUR(J20-I20)+MINUTE(J20-I20)/60 -> 0 | Q20: 3.Loại Lưới : | R20: 3,0mm | S20: 1.0416667 | V20: 40.03 | W20: 12.5 | X20: 34 | Y20: thanh | Z20: 132 | AA20: 60 | AB20: 100 | AC20: 101 | AD20: 119 | AE20: 30 | AI20: =IFERROR((AH20-AG20),"") -> 0 | AL20: =IFERROR((AK20-AJ20),"") -> 0 | AO20: =IFERROR((AN20-AM20),"") -> 0 | AR20: =IFERROR((AQ20-AP20),"") -> 0
H21: =HOUR(G21-F21)+MINUTE(G21-F21)/60 -> 0 | K21: =HOUR(J21-I21)+MINUTE(J21-I21)/60 -> 0 | S21: 1.0833333 | V21: 40.26 | W21: 12.5 | X21: 33 | Y21: thanh | Z21: 134 | AA21: 60 | AB21: 100 | AC21: 101 | AD21: 120 | AE21: 30 | AI21: =IFERROR((AH21-AG21),"") -> 0 | AL21: =IFERROR((AK21-AJ21),"") -> 0 | AO21: =IFERROR((AN21-AM21),"") -> 0 | AR21: =IFERROR((AQ21-AP21),"") -> 0
H22: =HOUR(G22-F22)+MINUTE(G22-F22)/60 -> 0 | K22: =HOUR(J22-I22)+MINUTE(J22-I22)/60 -> 0 | S22: 1.125 | V22: 41.03 | W22: 12.5 | X22: 33 | Y22: thanh | Z22: 135 | AA22: 60 | AB22: 100 | AC22: 101 | AD22: 120 | AE22: 30 | AI22: =IFERROR((AH22-AG22),"") -> 0 | AL22: =IFERROR((AK22-AJ22),"") -> 0 | AO22: =IFERROR((AN22-AM22),"") -> 0 | AR22: =IFERROR((AQ22-AP22),"") -> 0
H23: =HOUR(G23-F23)+MINUTE(G23-F23)/60 -> 0 | K23: =HOUR(J23-I23)+MINUTE(J23-I23)/60 -> 0 | S23: 1.1666667 | V23: 40.12 | W23: 12.5 | X23: 33 | Y23: thanh | Z23: 130 | AA23: 60 | AB23: 100 | AC23: 101 | AD23: 118 | AE23: 30 | AI23: =IFERROR((AH23-AG23),"") -> 0 | AL23: =IFERROR((AK23-AJ23),"") -> 0 | AO23: =IFERROR((AN23-AM23),"") -> 0 | AR23: =IFERROR((AQ23-AP23),"") -> 0
H24: =HOUR(G24-F24)+MINUTE(G24-F24)/60 -> 0 | K24: =HOUR(J24-I24)+MINUTE(J24-I24)/60 -> 0 | S24: 1.2083333 | V24: 40.08 | W24: 12.5 | X24: 33 | Y24: thanh | Z24: 129 | AA24: 60 | AB24: 100 | AC24: 101 | AD24: 119 | AE24: 30 | AI24: =IFERROR((AH24-AG24),"") -> 0 | AL24: =IFERROR((AK24-AJ24),"") -> 0 | AO24: =IFERROR((AN24-AM24),"") -> 0 | AR24: =IFERROR((AQ24-AP24),"") -> 0
H25: =HOUR(G25-F25)+MINUTE(G25-F25)/60 -> 0 | K25: =HOUR(J25-I25)+MINUTE(J25-I25)/60 -> 0 | S25: 1.25 | V25: 40.11 | W25: 12.5 | X25: 33 | Y25: thanh | Z25: 131 | AA25: 60 | AB25: 100 | AC25: 101 | AD25: 119 | AE25: 30 | AI25: =IFERROR((AH25-AG25),"") -> 0 | AL25: =IFERROR((AK25-AJ25),"") -> 0 | AO25: =IFERROR((AN25-AM25),"") -> 0 | AR25: =IFERROR((AQ25-AP25),"") -> 0
H26: =HOUR(G26-F26)+MINUTE(G26-F26)/60 -> 0 | K26: =HOUR(J26-I26)+MINUTE(J26-I26)/60 -> 0 | AI26: =IFERROR((AH26-AG26),"") -> 0 | AL26: =IFERROR((AK26-AJ26),"") -> 0 | AO26: =IFERROR((AN26-AM26),"") -> 0 | AR26: =IFERROR((AQ26-AP26),"") -> 0
H27: =HOUR(G27-F27)+MINUTE(G27-F27)/60 -> 0 | K27: =HOUR(J27-I27)+MINUTE(J27-I27)/60 -> 0 | AI27: =IFERROR((AH27-AG27),"") -> 0 | AL27: =IFERROR((AK27-AJ27),"") -> 0 | AO27: =IFERROR((AN27-AM27),"") -> 0 | AR27: =IFERROR((AQ27-AP27),"") -> 0
H28: =HOUR(G28-F28)+MINUTE(G28-F28)/60 -> 0 | K28: =HOUR(J28-I28)+MINUTE(J28-I28)/60 -> 0 | AI28: =IFERROR((AH28-AG28),"") -> 0 | AL28: =IFERROR((AK28-AJ28),"") -> 0 | AO28: =IFERROR((AN28-AM28),"") -> 0 | AR28: =IFERROR((AQ28-AP28),"") -> 0
H29: =HOUR(G29-F29)+MINUTE(G29-F29)/60 -> 0 | K29: =HOUR(J29-I29)+MINUTE(J29-I29)/60 -> 0 | AI29: =IFERROR((AH29-AG29),"") -> 0 | AL29: =IFERROR((AK29-AJ29),"") -> 0 | AO29: =IFERROR((AN29-AM29),"") -> 0 | AR29: =IFERROR((AQ29-AP29),"") -> 0
H30: =HOUR(G30-F30)+MINUTE(G30-F30)/60 -> 0 | K30: =HOUR(J30-I30)+MINUTE(J30-I30)/60 -> 0 | AI30: =IFERROR((AH30-AG30),"") -> 0 | AL30: =IFERROR((AK30-AJ30),"") -> 0 | AO30: =IFERROR((AN30-AM30),"") -> 0 | AR30: =IFERROR((AQ30-AP30),"") -> 0
H31: =HOUR(G31-F31)+MINUTE(G31-F31)/60 -> 0 | K31: =HOUR(J31-I31)+MINUTE(J31-I31)/60 -> 0 | AI31: =IFERROR((AH31-AG31),"") -> 0 | AL31: =IFERROR((AK31-AJ31),"") -> 0 | AO31: =IFERROR((AN31-AM31),"") -> 0 | AR31: =IFERROR((AQ31-AP31),"") -> 0
H32: =HOUR(G32-F32)+MINUTE(G32-F32)/60 -> 0 | K32: =HOUR(J32-I32)+MINUTE(J32-I32)/60 -> 0 | AI32: =IFERROR((AH32-AG32),"") -> 0 | AL32: =IFERROR((AK32-AJ32),"") -> 0 | AO32: =IFERROR((AN32-AM32),"") -> 0 | AR32: =IFERROR((AQ32-AP32),"") -> 0
H33: =HOUR(G33-F33)+MINUTE(G33-F33)/60 -> 0 | K33: =HOUR(J33-I33)+MINUTE(J33-I33)/60 -> 0 | AI33: =IFERROR((AH33-AG33),"") -> 0 | AL33: =IFERROR((AK33-AJ33),"") -> 0 | AO33: =IFERROR((AN33-AM33),"") -> 0 | AR33: =IFERROR((AQ33-AP33),"") -> 0
H34: =HOUR(G34-F34)+MINUTE(G34-F34)/60 -> 0 | K34: =HOUR(J34-I34)+MINUTE(J34-I34)/60 -> 0 | AI34: =IFERROR((AH34-AG34),"") -> 0 | AL34: =IFERROR((AK34-AJ34),"") -> 0 | AO34: =IFERROR((AN34-AM34),"") -> 0 | AR34: =IFERROR((AQ34-AP34),"") -> 0
H35: =HOUR(G35-F35)+MINUTE(G35-F35)/60 -> 0 | K35: =HOUR(J35-I35)+MINUTE(J35-I35)/60 -> 0 | AI35: =IFERROR((AH35-AG35),"") -> 0 | AL35: =IFERROR((AK35-AJ35),"") -> 0 | AO35: =IFERROR((AN35-AM35),"") -> 0 | AR35: =IFERROR((AQ35-AP35),"") -> 0
H36: =HOUR(G36-F36)+MINUTE(G36-F36)/60 -> 0 | K36: =HOUR(J36-I36)+MINUTE(J36-I36)/60 -> 0 | AI36: =IFERROR((AH36-AG36),"") -> 0 | AL36: =IFERROR((AK36-AJ36),"") -> 0 | AO36: =IFERROR((AN36-AM36),"") -> 0 | AR36: =IFERROR((AQ36-AP36),"") -> 0
H37: =HOUR(G37-F37)+MINUTE(G37-F37)/60 -> 0 | K37: =HOUR(J37-I37)+MINUTE(J37-I37)/60 -> 0 | AI37: =IFERROR((AH37-AG37),"") -> 0 | AL37: =IFERROR((AK37-AJ37),"") -> 0 | AO37: =IFERROR((AN37-AM37),"") -> 0 | AR37: =IFERROR((AQ37-AP37),"") -> 0
... H44: =HOUR(G44-F44)+MINUTE(G44-F44)/60 -> 0 | K44: =HOUR(J44-I44)+MINUTE(J44-I44)/60 -> 0 | AI44: =IFERROR((AH44-AG44),"") -> 0 | AL44: =IFERROR((AK44-AJ44),"") -> 0 | AO44: =IFERROR((AN44-AM44),"") -> 0 | AR44: =IFERROR((AQ44-AP44),"") -> 0
A46: QT-NL-01/BM15…………
A47: Lần ban hành: …06…………
...

Sheet 4
A1: CÔNG TY CỔ PHẦN CHĂN NUÔI C.P VIỆT NAM
A2: Chi Nhánh Tại Bình Dương
A3: Phòng Kho Nguyên Liệu
A4: BÁO CÁO VẬN HÀNH VÀ KIỂM SOÁT QUÁ TRÌNH HẤP NGUYÊN LIỆU
Z5: Ngày:.….04..…../…06.../……2026…….
A6: Ca | B6: Nguyên liệu | C6: Từ bồn | D6: Đến bồn | E6: Sản lượng (tấn) | F6: Thời gian chạy | I6: Thời gian ngưng | M6: Lý do ngưng | Q6: KẾT QUẢ KIỂM TRA CHẤT LƯỢNG | Z6: Ampe máy hấp | AA6: % Feeder | AB6: Nhiệt độ hơi (°C) | AC6: Nhiệt độ máy | AG6: Điện sử dụng máy hấp | AJ6: Hơi nóng sử dụng | AM6: Điện sử dụng LINE | AP6: Điện sử dụng máy nghiền
F7: Bắt đầu | G7: Kết thúc | H7: Tổng cộng | I7: Bắt đầu | J7: Kết thúc | K7: Tổng cộng | M7: 1 | O7: 2 | Q7: Mẫu trước hấp | S7: Mẫu sau hấp | AC7: Conditioner | AD7: Extruder | AE7: Môi trường | AG7: Số đầu | AH7: Số cuối | AI7: KWh | AJ7: Số đầu | AK7: Số cuối | AL7: Kg hơi | AM7: Số đầu | AN7: Số cuối | AO7: KWh | AP7: Số đầu | AQ7: Số cuối | AR7: KWh
K8: 1 | L8: 2 | M8: Mã số | N8: Số lần | O8: Mã số | P8: Số lần | S8: Thời gian lấy mẫu | T8: Đậu nành | V8: Bắp | W8: %M | X8: Nhiệt độ Cooler | Y8: Người kiểm tra
T9: Chỉ số PS | U9: Chỉ số Trypsin | V9: Chỉ số Hydro
A10: 1 | B10: CORN | C10: 1 | D10: 30 | E10: 26 | F10: 0.25 | G10: 0.375 | H10: =HOUR(G10-F10)+MINUTE(G10-F10)/60 -> 3 | I10: 0.375 | J10: 0.48958333 | K10: =HOUR(J10-I10)+MINUTE(J10-I10)/60 -> 2.75 | M10: 153 | N10: 1 | Q10: Đặc điểm về cảm quang: | S10: 0.29166667 | V10: 40.12 | W10: 12.5 | X10: 33 | Y10: quyết | Z10: 130 | AA10: 60 | AB10: 100 | AC10: 101 | AD10: 118 | AE10: 31 | AG10: 40689 | AH10: 40972 | AI10: =IFERROR((AH10-AG10),"") -> 283 | AJ10: 9203648 | AK10: 9203734 | AL10: =IFERROR((AK10-AJ10),"") -> 86 | AM10: 958070 | AN10: 958153 | AO10: =IFERROR((AN10-AM10),"") -> 83 | AP10: 365790 | AQ10: 365971 | AR10: =IFERROR((AQ10-AP10),"") -> 181
H11: =HOUR(G11-F11)+MINUTE(G11-F11)/60 -> 0 | K11: =HOUR(J11-I11)+MINUTE(J11-I11)/60 -> 0 | Q11: 1.Trong chuẩn | R11: v | S11: 0.33333333 | V11: 40.21 | W11: 12.5 | X11: 34 | Y11: quyết | Z11: 133 | AA11: 60 | AB11: 100 | AC11: 102 | AD11: 118 | AE11: 31 | AI11: =IFERROR((AH11-AG11),"") -> 0 | AL11: =IFERROR((AK11-AJ11),"") -> 0 | AO11: =IFERROR((AN11-AM11),"") -> 0 | AR11: =IFERROR((AQ11-AP11),"") -> 0
H12: =HOUR(G12-F12)+MINUTE(G12-F12)/60 -> 0 | K12: =HOUR(J12-I12)+MINUTE(J12-I12)/60 -> 0 | Q12: 2.Ngoài chuẩn | AI12: =IFERROR((AH12-AG12),"") -> 0 | AL12: =IFERROR((AK12-AJ12),"") -> 0 | AO12: =IFERROR((AN12-AM12),"") -> 0 | AR12: =IFERROR((AQ12-AP12),"") -> 0
H13: =HOUR(G13-F13)+MINUTE(G13-F13)/60 -> 0 | K13: =HOUR(J13-I13)+MINUTE(J13-I13)/60 -> 0 | Q13: 3.Loại Lưới : | R13: 3,0mm | AI13: =IFERROR((AH13-AG13),"") -> 0 | AL13: =IFERROR((AK13-AJ13),"") -> 0 | AO13: =IFERROR((AN13-AM13),"") -> 0 | AR13: =IFERROR((AQ13-AP13),"") -> 0
A14: 1 | B14: FFS | C14: 4 | D14: 39 | E14: 12 | F14: 0.48958333 | G14: 0.58333333 | H14: =HOUR(G14-F14)+MINUTE(G14-F14)/60 -> 2.25 | K14: =HOUR(J14-I14)+MINUTE(J14-I14)/60 -> 0 | Q14: Đặc điểm về cảm quang: | S14: 0.5 | T14: 79.81 | U14: 9.44 | W14: 10.9 | X14: 33 | Y14: quyết | Z14: 113 | AA14: 60 | AB14: 100 | AC14: 101 | AD14: 133 | AE14: 32 | AG14: 636644 | AH14: 636773 | AI14: =IFERROR((AH14-AG14),"") -> 129 | AJ14: 28852 | AK14: 29774 | AL14: =IFERROR((AK14-AJ14),"") -> 922 | AM14: 958153 | AN14: 958218 | AO14: =IFERROR((AN14-AM14),"") -> 65 | AP14: 365971 | AQ14: 366136 | AR14: =IFERROR((AQ14-AP14),"") -> 165
H15: =HOUR(G15-F15)+MINUTE(G15-F15)/60 -> 0 | K15: =HOUR(J15-I15)+MINUTE(J15-I15)/60 -> 0 | Q15: 1.Trong chuẩn | R15: v | S15: 0.54166667 | T15: 78.98 | U15: 9.35 | W15: 10.9 | X15: 33 | Y15: quyết | Z15: 109 | AA15: 60 | AB15: 100 | AC15: 101 | AD15: 133 | AE15: 32 | AI15: =IFERROR((AH15-AG15),"") -> 0 | AL15: =IFERROR((AK15-AJ15),"") -> 0 | AO15: =IFERROR((AN15-AM15),"") -> 0 | AR15: =IFERROR((AQ15-AP15),"") -> 0
H16: =HOUR(G16-F16)+MINUTE(G16-F16)/60 -> 0 | K16: =HOUR(J16-I16)+MINUTE(J16-I16)/60 -> 0 | Q16: 2.Ngoài chuẩn | AI16: =IFERROR((AH16-AG16),"") -> 0 | AL16: =IFERROR((AK16-AJ16),"") -> 0 | AO16: =IFERROR((AN16-AM16),"") -> 0 | AR16: =IFERROR((AQ16-AP16),"") -> 0
H17: =HOUR(G17-F17)+MINUTE(G17-F17)/60 -> 0 | K17: =HOUR(J17-I17)+MINUTE(J17-I17)/60 -> 0 | Q17: 3.Loại Lưới : | R17: 2,5mm | AI17: =IFERROR((AH17-AG17),"") -> 0 | AL17: =IFERROR((AK17-AJ17),"") -> 0 | AO17: =IFERROR((AN17-AM17),"") -> 0 | AR17: =IFERROR((AQ17-AP17),"") -> 0
A18: 2 | B18: FFS | C18: 4 | D18: 39 | E18: 13 | F18: 0.58333333 | G18: 0.6875 | H18: =HOUR(G18-F18)+MINUTE(G18-F18)/60 -> 2.5 | I18: 0.6875 | J18: 0.91666667 | K18: =HOUR(J18-I18)+MINUTE(J18-I18)/60 -> 5.5 | M18: 153 | N18: 1 | Q18: Đặc điểm về cảm quang: | S18: 0.625 | T18: 80.01 | U18: 9.77 | W18: 10.9 | X18: 33 | Y18: quyết | Z18: 113 | AA18: 60 | AB18: 100 | AC18: 101 | AD18: 133 | AE18: 31 | AG18: 636773 | AH18: 636934 | AI18: =IFERROR((AH18-AG18),"") -> 161 | AJ18: 29774 | AK18: 31151 | AL18: =IFERROR((AK18-AJ18),"") -> 1377 | AM18: 958218 | AN18: 958286 | AO18: =IFERROR((AN18-AM18),"") -> 68 | AP18: 366136 | AQ18: 366343 | AR18: =IFERROR((AQ18-AP18),"") -> 207
H19: =HOUR(G19-F19)+MINUTE(G19-F19)/60 -> 0 | K19: =HOUR(J19-I19)+MINUTE(J19-I19)/60 -> 0 | Q19: 1.Trong chuẩn | R19: v | S19: 0.66666667 | T19: 79.51 | U19: 9.64 | W19: 10.9 | X19: 33 | Y19: quyết | Z19: 109 | AA19: 60 | AB19: 100 | AC19: 101 | AD19: 133 | AE19: 31 | AI19: =IFERROR((AH19-AG19),"") -> 0 | AL19: =IFERROR((AK19-AJ19),"") -> 0 | AO19: =IFERROR((AN19-AM19),"") -> 0 | AR19: =IFERROR((AQ19-AP19),"") -> 0
H20: =HOUR(G20-F20)+MINUTE(G20-F20)/60 -> 0 | K20: =HOUR(J20-I20)+MINUTE(J20-I20)/60 -> 0 | Q20: 2.Ngoài chuẩn | AI20: =IFERROR((AH20-AG20),"") -> 0 | AL20: =IFERROR((AK20-AJ20),"") -> 0 | AO20: =IFERROR((AN20-AM20),"") -> 0 | AR20: =IFERROR((AQ20-AP20),"") -> 0
A21: 3 | B21: CORN | H21: =HOUR(G21-F21)+MINUTE(G21-F21)/60 -> 0 | I21: 0.91666667 | J21: 1.25 | K21: =HOUR(J21-I21)+MINUTE(J21-I21)/60 -> 8 | M21: 502 | N21: 1 | Q21: 3.Loại Lưới : | R21: 2,5mm | AI21: =IFERROR((AH21-AG21),"") -> 0 | AL21: =IFERROR((AK21-AJ21),"") -> 0 | AO21: =IFERROR((AN21-AM21),"") -> 0 | AR21: =IFERROR((AQ21-AP21),"") -> 0
H22: =HOUR(G22-F22)+MINUTE(G22-F22)/60 -> 0 | K22: =HOUR(J22-I22)+MINUTE(J22-I22)/60 -> 0 | AI22: =IFERROR((AH22-AG22),"") -> 0 | AL22: =IFERROR((AK22-AJ22),"") -> 0 | AO22: =IFERROR((AN22-AM22),"") -> 0 | AR22: =IFERROR((AQ22-AP22),"") -> 0
H23: =HOUR(G23-F23)+MINUTE(G23-F23)/60 -> 0 | K23: =HOUR(J23-I23)+MINUTE(J23-I23)/60 -> 0 | AI23: =IFERROR((AH23-AG23),"") -> 0 | AL23: =IFERROR((AK23-AJ23),"") -> 0 | AO23: =IFERROR((AN23-AM23),"") -> 0 | AR23: =IFERROR((AQ23-AP23),"") -> 0
H24: =HOUR(G24-F24)+MINUTE(G24-F24)/60 -> 0 | K24: =HOUR(J24-I24)+MINUTE(J24-I24)/60 -> 0 | AI24: =IFERROR((AH24-AG24),"") -> 0 | AL24: =IFERROR((AK24-AJ24),"") -> 0 | AO24: =IFERROR((AN24-AM24),"") -> 0 | AR24: =IFERROR((AQ24-AP24),"") -> 0
H25: =HOUR(G25-F25)+MINUTE(G25-F25)/60 -> 0 | K25: =HOUR(J25-I25)+MINUTE(J25-I25)/60 -> 0 | AI25: =IFERROR((AH25-AG25),"") -> 0 | AL25: =IFERROR((AK25-AJ25),"") -> 0 | AO25: =IFERROR((AN25-AM25),"") -> 0 | AR25: =IFERROR((AQ25-AP25),"") -> 0
H26: =HOUR(G26-F26)+MINUTE(G26-F26)/60 -> 0 | K26: =HOUR(J26-I26)+MINUTE(J26-I26)/60 -> 0 | AI26: =IFERROR((AH26-AG26),"") -> 0 | AL26: =IFERROR((AK26-AJ26),"") -> 0 | AO26: =IFERROR((AN26-AM26),"") -> 0 | AR26: =IFERROR((AQ26-AP26),"") -> 0
H27: =HOUR(G27-F27)+MINUTE(G27-F27)/60 -> 0 | K27: =HOUR(J27-I27)+MINUTE(J27-I27)/60 -> 0 | AI27: =IFERROR((AH27-AG27),"") -> 0 | AL27: =IFERROR((AK27-AJ27),"") -> 0 | AO27: =IFERROR((AN27-AM27),"") -> 0 | AR27: =IFERROR((AQ27-AP27),"") -> 0
H28: =HOUR(G28-F28)+MINUTE(G28-F28)/60 -> 0 | K28: =HOUR(J28-I28)+MINUTE(J28-I28)/60 -> 0 | AI28: =IFERROR((AH28-AG28),"") -> 0 | AL28: =IFERROR((AK28-AJ28),"") -> 0 | AO28: =IFERROR((AN28-AM28),"") -> 0 | AR28: =IFERROR((AQ28-AP28),"") -> 0
H29: =HOUR(G29-F29)+MINUTE(G29-F29)/60 -> 0 | K29: =HOUR(J29-I29)+MINUTE(J29-I29)/60 -> 0 | AI29: =IFERROR((AH29-AG29),"") -> 0 | AL29: =IFERROR((AK29-AJ29),"") -> 0 | AO29: =IFERROR((AN29-AM29),"") -> 0 | AR29: =IFERROR((AQ29-AP29),"") -> 0
H30: =HOUR(G30-F30)+MINUTE(G30-F30)/60 -> 0 | K30: =HOUR(J30-I30)+MINUTE(J30-I30)/60 -> 0 | AI30: =IFERROR((AH30-AG30),"") -> 0 | AL30: =IFERROR((AK30-AJ30),"") -> 0 | AO30: =IFERROR((AN30-AM30),"") -> 0 | AR30: =IFERROR((AQ30-AP30),"") -> 0
H31: =HOUR(G31-F31)+MINUTE(G31-F31)/60 -> 0 | K31: =HOUR(J31-I31)+MINUTE(J31-I31)/60 -> 0 | AI31: =IFERROR((AH31-AG31),"") -> 0 | AL31: =IFERROR((AK31-AJ31),"") -> 0 | AO31: =IFERROR((AN31-AM31),"") -> 0 | AR31: =IFERROR((AQ31-AP31),"") -> 0
H32: =HOUR(G32-F32)+MINUTE(G32-F32)/60 -> 0 | K32: =HOUR(J32-I32)+MINUTE(J32-I32)/60 -> 0 | AI32: =IFERROR((AH32-AG32),"") -> 0 | AL32: =IFERROR((AK32-AJ32),"") -> 0 | AO32: =IFERROR((AN32-AM32),"") -> 0 | AR32: =IFERROR((AQ32-AP32),"") -> 0
H33: =HOUR(G33-F33)+MINUTE(G33-F33)/60 -> 0 | K33: =HOUR(J33-I33)+MINUTE(J33-I33)/60 -> 0 | AI33: =IFERROR((AH33-AG33),"") -> 0 | AL33: =IFERROR((AK33-AJ33),"") -> 0 | AO33: =IFERROR((AN33-AM33),"") -> 0 | AR33: =IFERROR((AQ33-AP33),"") -> 0
... H44: =HOUR(G44-F44)+MINUTE(G44-F44)/60 -> 0 | K44: =HOUR(J44-I44)+MINUTE(J44-I44)/60 -> 0 | AI44: =IFERROR((AH44-AG44),"") -> 0 | AL44: =IFERROR((AK44-AJ44),"") -> 0 | AO44: =IFERROR((AN44-AM44),"") -> 0 | AR44: =IFERROR((AQ44-AP44),"") -> 0
A46: QT-NL-01/BM15…………
A47: Lần ban hành: …06…………
A48: Ngày hiệu lực: …01/10/2025… | I48: Người Báo Cáo :……………………………… | S48: Người Thẩm Tra :…………………………………….
B51: Tổng cộng (tấn) | E51: =SUM(E10:E44) -> 51 | F51: Tổng cộng (giờ) | H51: =SUM(H10:H44) -> 7.75 | I51: Tổng cộng (giờ) | K51: =SUM(K10:L44) -> 16.25 | Q51: (Ghi chú: Chất lượng cảm quan chọn: Đ/KĐ) | Y51: Sản phẩm chạy lại (tấn) | AC51: 2 | AG51: Tổng cộng (KW) | AI51: =SUM(AI10:AI44) -> 573 | AJ51: Tổng cộng (Kg) | AL51: =SUM(AL10:AL44) -> 2385 | AM51: Tổng cộng (KW) | AO51: =SUM(AO10:AO44) -> 216 | AP51: Tổng cộng (KW) | AR51: =SUM(AR10:AR44) -> 553
H53: Tồn trước | K53: Tồn sau | R53: Tấn/ngày | T53: Tấn/giờ | W53: KWh ngày | Y53: KWh/tấn | AB53: Kg hơi/ngày | AH53: Kg hơi/tấn | AL53: Nhân viên vận hành | AP53: Người thẩm tra
A54: QT-NL-01/BM15 Lần ban hành: 02 Ngày ban hành: 15/07/2019 | G54: CORN | H54: =SUM('3'!K54:Q54) -> 157 | K54: =H54+R54 -> 183 | R54: =SUMIF($B$10:$B$44,G54,$E$10:$E$44) -> 26 | T54: =IFERROR(R54/SUMIF($B$10:$B$44,G54,$H$10:$H$44),"") -> 8.6666667 | W54: =SUMIF($B$10:$B$44,G54,$AI$10:$AI$44)+SUMIF($B$10:$B$44,G54,$AO$10:$AO$44)+SUMIF($B$10:$B$44,G54,$AR$10:$AR$44) -> 547 | Y54: =IFERROR(W54/R54,"") -> 21.038462 | AB54: =SUMIF($B$10:$B$44,G54,$AL$10:$AL$44) -> 86 | AH54: =IFERROR(AB54/R54,"") -> 3.3076923 | AL54: Ca 1 | AM54: quyết | AP54: lê văn lộc
...

Sheet 5
A1: CÔNG TY CỔ PHẦN CHĂN NUÔI C.P VIỆT NAM
A2: Chi Nhánh Tại Bình Dương
A3: Phòng Kho Nguyên Liệu
A4: BÁO CÁO VẬN HÀNH VÀ KIỂM SOÁT QUÁ TRÌNH HẤP NGUYÊN LIỆU
Z5: Ngày:.…..05.…../…06.../……2026.…….
A6: Ca | B6: Nguyên liệu | C6: Từ bồn | D6: Đến bồn | E6: Sản lượng (tấn) | F6: Thời gian chạy | I6: Thời gian ngưng | M6: Lý do ngưng | Q6: KẾT QUẢ KIỂM TRA CHẤT LƯỢNG | Z6: Ampe máy hấp | AA6: % Feeder | AB6: Nhiệt độ hơi (°C) | AC6: Nhiệt độ máy | AG6: Điện sử dụng máy hấp | AJ6: Hơi nóng sử dụng | AM6: Điện sử dụng LINE | AP6: Điện sử dụng máy nghiền
F7: Bắt đầu | G7: Kết thúc | H7: Tổng cộng | I7: Bắt đầu | J7: Kết thúc | K7: Tổng cộng | M7: 1 | O7: 2 | Q7: Mẫu trước hấp | S7: Mẫu sau hấp | AC7: Conditioner | AD7: Extruder | AE7: Môi trường | AG7: Số đầu | AH7: Số cuối | AI7: KWh | AJ7: Số đầu | AK7: Số cuối | AL7: Kg hơi | AM7: Số đầu | AN7: Số cuối | AO7: KWh | AP7: Số đầu | AQ7: Số cuối | AR7: KWh
K8: 1 | L8: 2 | M8: Mã số | N8: Số lần | O8: Mã số | P8: Số lần | S8: Thời gian lấy mẫu | T8: Đậu nành | V8: Bắp | W8: %M | X8: Nhiệt độ Cooler | Y8: Người kiểm tra
T9: Chỉ số PS | U9: Chỉ số Trypsin | V9: Chỉ số Hydro
A10: 1 | H10: =HOUR(G10-F10)+MINUTE(G10-F10)/60 -> 0 | I10: 0.25 | J10: 0.5 | K10: =HOUR(J10-I10)+MINUTE(J10-I10)/60 -> 6 | M10: 153 | N10: 1 | Q10: Đặc điểm về cảm quang: | AI10: =IFERROR((AH10-AG10),"") -> 0 | AL10: =IFERROR((AK10-AJ10),"") -> 0 | AO10: =IFERROR((AN10-AM10),"") -> 0 | AR10: =IFERROR((AQ10-AP10),"") -> 0
A11: 1 | B11: FFS | C11: 4 | D11: 39 | E11: 12 | F11: 0.5 | G11: 0.58333333 | H11: =HOUR(G11-F11)+MINUTE(G11-F11)/60 -> 2 | K11: =HOUR(J11-I11)+MINUTE(J11-I11)/60 -> 0 | Q11: 1.Trong chuẩn | R11: v | S11: 0.5 | T11: 79.55 | U11: 9.34 | W11: 10.9 | X11: 33 | Y11: quyết | Z11: 113 | AA11: 63 | AB11: 100 | AC11: 101 | AD11: 133 | AE11: 32 | AG11: 636934 | AH11: 637065 | AI11: =IFERROR((AH11-AG11),"") -> 131 | AJ11: 31151 | AK11: 32350 | AL11: =IFERROR((AK11-AJ11),"") -> 1199 | AM11: 958286 | AN11: 958348 | AO11: =IFERROR((AN11-AM11),"") -> 62 | AP11: 366343 | AQ11: 366502 | AR11: =IFERROR((AQ11-AP11),"") -> 159
H12: =HOUR(G12-F12)+MINUTE(G12-F12)/60 -> 0 | K12: =HOUR(J12-I12)+MINUTE(J12-I12)/60 -> 0 | Q12: 2.Ngoài chuẩn | S12: 0.54166667 | T12: 79.64 | U12: 9.11 | W12: 10.9 | X12: 33 | Y12: quyết | Z12: 109 | AA12: 63 | AB12: 100 | AC12: 101 | AD12: 133 | AE12: 32 | AI12: =IFERROR((AH12-AG12),"") -> 0 | AL12: =IFERROR((AK12-AJ12),"") -> 0 | AO12: =IFERROR((AN12-AM12),"") -> 0 | AR12: =IFERROR((AQ12-AP12),"") -> 0
H13: =HOUR(G13-F13)+MINUTE(G13-F13)/60 -> 0 | K13: =HOUR(J13-I13)+MINUTE(J13-I13)/60 -> 0 | Q13: 3.Loại Lưới : | R13: 2,5mm | AI13: =IFERROR((AH13-AG13),"") -> 0 | AL13: =IFERROR((AK13-AJ13),"") -> 0 | AO13: =IFERROR((AN13-AM13),"") -> 0 | AR13: =IFERROR((AQ13-AP13),"") -> 0
A14: 2 | B14: FFS | C14: 4 | D14: 39 | E14: 14 | F14: 0.58333333 | G14: 0.6875 | H14: =HOUR(G14-F14)+MINUTE(G14-F14)/60 -> 2.5 | I14: 0.6875 | J14: 0.91666667 | K14: =HOUR(J14-I14)+MINUTE(J14-I14)/60 -> 5.5 | M14: 153 | N14: 1 | Q14: 1.Trong chuẩn | R14: v | S14: 0.58333333 | T14: 79.4 | U14: 9.6 | W14: 10.8 | X14: 34 | Y14: tính | Z14: 116 | AA14: 60 | AB14: 100 | AC14: 102 | AD14: 133 | AE14: 33 | AG14: 637065 | AH14: 637236 | AI14: =IFERROR((AH14-AG14),"") -> 171 | AJ14: 32350 | AK14: 33566 | AL14: =IFERROR((AK14-AJ14),"") -> 1216 | AM14: 958348 | AN14: 958409 | AO14: =IFERROR((AN14-AM14),"") -> 61 | AP14: 366502 | AQ14: 366708 | AR14: =IFERROR((AQ14-AP14),"") -> 206
H15: =HOUR(G15-F15)+MINUTE(G15-F15)/60 -> 0 | K15: =HOUR(J15-I15)+MINUTE(J15-I15)/60 -> 0 | Q15: 2.Ngoài chuẩn | S15: 0.625 | T15: 80.1 | U15: 8.8 | W15: 10.8 | X15: 35 | Y15: tính | Z15: 114 | AA15: 60 | AB15: 100 | AC15: 101 | AD15: 134 | AE15: 33 | AI15: =IFERROR((AH15-AG15),"") -> 0 | AL15: =IFERROR((AK15-AJ15),"") -> 0 | AO15: =IFERROR((AN15-AM15),"") -> 0 | AR15: =IFERROR((AQ15-AP15),"") -> 0
H16: =HOUR(G16-F16)+MINUTE(G16-F16)/60 -> 0 | K16: =HOUR(J16-I16)+MINUTE(J16-I16)/60 -> 0 | Q16: 3.Loại Lưới : | R16: 2,5mm | S16: 0.66666667 | T16: 78.9 | U16: 9.1 | W16: 10.8 | X16: 34 | Y16: tính | Z16: 110 | AA16: 60 | AB16: 100 | AC16: 101 | AD16: 134 | AE16: 33 | AI16: =IFERROR((AH16-AG16),"") -> 0 | AL16: =IFERROR((AK16-AJ16),"") -> 0 | AO16: =IFERROR((AN16-AM16),"") -> 0 | AR16: =IFERROR((AQ16-AP16),"") -> 0
A17: 3 | H17: =HOUR(G17-F17)+MINUTE(G17-F17)/60 -> 0 | I17: 0.91666667 | J17: 1.25 | K17: =HOUR(J17-I17)+MINUTE(J17-I17)/60 -> 8 | M17: 152 | N17: 1 | AI17: =IFERROR((AH17-AG17),"") -> 0 | AL17: =IFERROR((AK17-AJ17),"") -> 0 | AO17: =IFERROR((AN17-AM17),"") -> 0 | AR17: =IFERROR((AQ17-AP17),"") -> 0
H18: =HOUR(G18-F18)+MINUTE(G18-F18)/60 -> 0 | K18: =HOUR(J18-I18)+MINUTE(J18-I18)/60 -> 0 | AI18: =IFERROR((AH18-AG18),"") -> 0 | AL18: =IFERROR((AK18-AJ18),"") -> 0 | AO18: =IFERROR((AN18-AM18),"") -> 0 | AR18: =IFERROR((AQ18-AP18),"") -> 0
H19: =HOUR(G19-F19)+MINUTE(G19-F19)/60 -> 0 | K19: =HOUR(J19-I19)+MINUTE(J19-I19)/60 -> 0 | AI19: =IFERROR((AH19-AG19),"") -> 0 | AL19: =IFERROR((AK19-AJ19),"") -> 0 | AO19: =IFERROR((AN19-AM19),"") -> 0 | AR19: =IFERROR((AQ19-AP19),"") -> 0
H20: =HOUR(G20-F20)+MINUTE(G20-F20)/60 -> 0 | K20: =HOUR(J20-I20)+MINUTE(J20-I20)/60 -> 0 | AI20: =IFERROR((AH20-AG20),"") -> 0 | AL20: =IFERROR((AK20-AJ20),"") -> 0 | AO20: =IFERROR((AN20-AM20),"") -> 0 | AR20: =IFERROR((AQ20-AP20),"") -> 0
H21: =HOUR(G21-F21)+MINUTE(G21-F21)/60 -> 0 | K21: =HOUR(J21-I21)+MINUTE(J21-I21)/60 -> 0 | AI21: =IFERROR((AH21-AG21),"") -> 0 | AL21: =IFERROR((AK21-AJ21),"") -> 0 | AO21: =IFERROR((AN21-AM21),"") -> 0 | AR21: =IFERROR((AQ21-AP21),"") -> 0
H22: =HOUR(G22-F22)+MINUTE(G22-F22)/60 -> 0 | K22: =HOUR(J22-I22)+MINUTE(J22-I22)/60 -> 0 | AI22: =IFERROR((AH22-AG22),"") -> 0 | AL22: =IFERROR((AK22-AJ22),"") -> 0 | AO22: =IFERROR((AN22-AM22),"") -> 0 | AR22: =IFERROR((AQ22-AP22),"") -> 0
H23: =HOUR(G23-F23)+MINUTE(G23-F23)/60 -> 0 | K23: =HOUR(J23-I23)+MINUTE(J23-I23)/60 -> 0 | AI23: =IFERROR((AH23-AG23),"") -> 0 | AL23: =IFERROR((AK23-AJ23),"") -> 0 | AO23: =IFERROR((AN23-AM23),"") -> 0 | AR23: =IFERROR((AQ23-AP23),"") -> 0
H24: =HOUR(G24-F24)+MINUTE(G24-F24)/60 -> 0 | K24: =HOUR(J24-I24)+MINUTE(J24-I24)/60 -> 0 | AI24: =IFERROR((AH24-AG24),"") -> 0 | AL24: =IFERROR((AK24-AJ24),"") -> 0 | AO24: =IFERROR((AN24-AM24),"") -> 0 | AR24: =IFERROR((AQ24-AP24),"") -> 0
H25: =HOUR(G25-F25)+MINUTE(G25-F25)/60 -> 0 | K25: =HOUR(J25-I25)+MINUTE(J25-I25)/60 -> 0 | AI25: =IFERROR((AH25-AG25),"") -> 0 | AL25: =IFERROR((AK25-AJ25),"") -> 0 | AO25: =IFERROR((AN25-AM25),"") -> 0 | AR25: =IFERROR((AQ25-AP25),"") -> 0
H26: =HOUR(G26-F26)+MINUTE(G26-F26)/60 -> 0 | K26: =HOUR(J26-I26)+MINUTE(J26-I26)/60 -> 0 | AI26: =IFERROR((AH26-AG26),"") -> 0 | AL26: =IFERROR((AK26-AJ26),"") -> 0 | AO26: =IFERROR((AN26-AM26),"") -> 0 | AR26: =IFERROR((AQ26-AP26),"") -> 0
H27: =HOUR(G27-F27)+MINUTE(G27-F27)/60 -> 0 | K27: =HOUR(J27-I27)+MINUTE(J27-I27)/60 -> 0 | AI27: =IFERROR((AH27-AG27),"") -> 0 | AL27: =IFERROR((AK27-AJ27),"") -> 0 | AO27: =IFERROR((AN27-AM27),"") -> 0 | AR27: =IFERROR((AQ27-AP27),"") -> 0
H28: =HOUR(G28-F28)+MINUTE(G28-F28)/60 -> 0 | K28: =HOUR(J28-I28)+MINUTE(J28-I28)/60 -> 0 | AI28: =IFERROR((AH28-AG28),"") -> 0 | AL28: =IFERROR((AK28-AJ28),"") -> 0 | AO28: =IFERROR((AN28-AM28),"") -> 0 | AR28: =IFERROR((AQ28-AP28),"") -> 0
H29: =HOUR(G29-F29)+MINUTE(G29-F29)/60 -> 0 | K29: =HOUR(J29-I29)+MINUTE(J29-I29)/60 -> 0 | AI29: =IFERROR((AH29-AG29),"") -> 0 | AL29: =IFERROR((AK29-AJ29),"") -> 0 | AO29: =IFERROR((AN29-AM29),"") -> 0 | AR29: =IFERROR((AQ29-AP29),"") -> 0
... H45: =HOUR(G45-F45)+MINUTE(G45-F45)/60 -> 0 | K45: =HOUR(J45-I45)+MINUTE(J45-I45)/60 -> 0 | AI45: =IFERROR((AH45-AG45),"") -> 0 | AL45: =IFERROR((AK45-AJ45),"") -> 0 | AO45: =IFERROR((AN45-AM45),"") -> 0 | AR45: =IFERROR((AQ45-AP45),"") -> 0
A47: QT-NL-01/BM15…………
A48: Lần ban hành: …06…………
A49: Ngày hiệu lực: …01/10/2025… | I49: Người Báo Cáo :……………………………… | S49: Người Thẩm Tra :…………………………………….
H52: =HOUR(G52-F52)+MINUTE(G52-F52)/60 -> 0 | K52: =HOUR(J52-I52)+MINUTE(J52-I52)/60 -> 0 | AI52: =IFERROR((AH52-AG52),"") -> 0 | AL52: =IFERROR((AK52-AJ52),"") -> 0 | AO52: =IFERROR((AN52-AM52),"") -> 0 | AR52: =IFERROR((AQ52-AP52),"") -> 0
B53: Tổng cộng (tấn) | E53: =SUM(E10:E52) -> 26 | F53: Tổng cộng (giờ) | H53: =SUM(H10:H52) -> 4.5 | I53: Tổng cộng (giờ) | K53: =SUM(K10:L52) -> 19.5 | Q53: (Ghi chú: Chất lượng cảm quan chọn: Đ/KĐ) | Y53: Sản phẩm chạy lại (tấn) | AG53: Tổng cộng (KW) | AI53: =SUM(AI10:AI52) -> 302 | AJ53: Tổng cộng (Kg) | AL53: =SUM(AL10:AL52) -> 2415 | AM53: Tổng cộng (KW) | AO53: =SUM(AO10:AO52) -> 123 | AP53: Tổng cộng (KW) | AR53: =SUM(AR10:AR52) -> 365
H55: Tồn trước | K55: Tồn sau | R55: Tấn/ngày | T55: Tấn/giờ | W55: KWh ngày | Y55: KWh/tấn | AB55: Kg hơi/ngày | AH55: Kg hơi/tấn | AL55: Nhân viên vận hành | AP55: Người thẩm tra
A56: QT-NL-01/BM15 Lần ban hành: 02 Ngày ban hành: 15/07/2019 | G56: CORN | H56: =SUM('4'!K54:Q54) -> 183 | K56: =H56+R56 -> 183 | R56: =SUMIF($B$10:$B$52,G56,$E$10:$E$52) -> 0 | T56: =IFERROR(R56/SUMIF($B$10:$B$52,G56,$H$10:$H$52),"") | W56: =SUMIF($B$10:$B$52,G56,$AI$10:$AI$52)+SUMIF($B$10:$B$52,G56,$AO$10:$AO$52)+SUMIF($B$10:$B$52,G56,$AR$10:$AR$52) -> 0 | Y56: =IFERROR(W56/R56,"") | AB56: =SUMIF($B$10:$B$52,G56,$AL$10:$AL$52) -> 0 | AH56: =IFERROR(AB56/R56,"") | AL56: Ca 1 | AM56: quyết | AP56: lê văn lộc
G57: FFS | H57: =SUM('4'!K55:Q55) -> 134 | K57: =H57+R57 -> 160 | R57: =SUMIF($B$10:$B$52,G57,$E$10:$E$52) -> 26 | T57: =IFERROR(R57/SUMIF($B$10:$B$52,G57,$H$10:$H$52),"") -> 5.7777778 | W57: =SUMIF($B$10:$B$52,G57,$AI$10:$AI$52)+SUMIF($B$10:$B$52,G57,$AO$10:$AO$52)+SUMIF($B$10:$B$52,G57,$AR$10:$AR$52) -> 790 | Y57: =IFERROR(W57/R57,"") -> 30.384615 | AB57: =SUMIF($B$10:$B$52,G57,$AL$10:$AL$52) -> 2415 | AH57: =IFERROR(AB57/R57,"") -> 92.884615 | AL57: Ca 2 | AM57: tính | AP57: Thẩm tra | AQ57: Ngày thẩm tra
G58: TỔNG | H58: =IFERROR(SUM(H56:J57),"") -> 317 | K58: =IFERROR(SUM(K56:Q57),"") -> 343 | R58: =IFERROR(SUM(R56:S57),"") -> 26 | T58: =IFERROR(AVERAGE(T56:U57),"") -> 5.7777778 | W58: =IFERROR(SUM(W56:X57),"") -> 790 | Y58: =IFERROR(AVERAGE(Y56:AA57),"") -> 30.384615 | AB58: =IFERROR(SUM(AB56:AG57),"") -> 2415 | AH58: =IFERROR(AVERAGE(AH56:AI57),"") -> 92.884615 | AL58: Ca 3 | AM58: thanh

Sheet 6
A1: CÔNG TY CỔ PHẦN CHĂN NUÔI C.P VIỆT NAM
A2: Chi Nhánh Tại Bình Dương
A3: Phòng Kho Nguyên Liệu
A4: BÁO CÁO VẬN HÀNH VÀ KIỂM SOÁT QUÁ TRÌNH HẤP NGUYÊN LIỆU
Z5: Ngày:.…..06.…../….06…../…2026….…….
A6: Ca | B6: Nguyên liệu | C6: Từ bồn | D6: Đến bồn | E6: Sản lượng (tấn) | F6: Thời gian chạy | I6: Thời gian ngưng | M6: Lý do ngưng | Q6: KẾT QUẢ KIỂM TRA CHẤT LƯỢNG | Z6: Ampe máy hấp | AA6: % Feeder | AB6: Nhiệt độ hơi (°C) | AC6: Nhiệt độ máy | AG6: Điện sử dụng máy hấp | AJ6: Hơi nóng sử dụng | AM6: Điện sử dụng LINE | AP6: Điện sử dụng máy nghiền
F7: Bắt đầu | G7: Kết thúc | H7: Tổng cộng | I7: Bắt đầu | J7: Kết thúc | K7: Tổng cộng | M7: 1 | O7: 2 | Q7: Mẫu trước hấp | S7: Mẫu sau hấp | AC7: Conditioner | AD7: Extruder | AE7: Môi trường | AG7: Số đầu | AH7: Số cuối | AI7: KWh | AJ7: Số đầu | AK7: Số cuối | AL7: Kg hơi | AM7: Số đầu | AN7: Số cuối | AO7: KWh | AP7: Số đầu | AQ7: Số cuối | AR7: KWh
K8: 1 | L8: 2 | M8: Mã số | N8: Số lần | O8: Mã số | P8: Số lần | S8: Thời gian lấy mẫu | T8: Đậu nành | V8: Bắp | W8: %M | X8: Nhiệt độ Cooler | Y8: Người kiểm tra
T9: Chỉ số PS | U9: Chỉ số Trypsin | V9: Chỉ số Hydro
H10: =HOUR(G10-F10)+MINUTE(G10-F10)/60 -> 0 | K10: =HOUR(J10-I10)+MINUTE(J10-I10)/60 -> 0 | Q10: Đặc điểm về cảm quang: | AI10: =IFERROR((AH10-AG10),"") -> 0 | AL10: =IFERROR((AK10-AJ10),"") -> 0 | AO10: =IFERROR((AN10-AM10),"") -> 0 | AR10: =IFERROR((AQ10-AP10),"") -> 0
A11: 1 | H11: =HOUR(G11-F11)+MINUTE(G11-F11)/60 -> 0 | I11: 0.25 | J11: 0.58333333 | K11: =HOUR(J11-I11)+MINUTE(J11-I11)/60 -> 8 | M11: 153 | N11: 1 | Q11: 1.Trong chuẩn | R11: v | AI11: =IFERROR((AH11-AG11),"") -> 0 | AL11: =IFERROR((AK11-AJ11),"") -> 0 | AO11: =IFERROR((AN11-AM11),"") -> 0 | AR11: =IFERROR((AQ11-AP11),"") -> 0
A12: 2 | H12: =HOUR(G12-F12)+MINUTE(G12-F12)/60 -> 0 | I12: 0.58333333 | J12: 0.91666667 | K12: =HOUR(J12-I12)+MINUTE(J12-I12)/60 -> 8 | M12: 153 | N12: 1 | Q12: 2.Ngoài chuẩn | AI12: =IFERROR((AH12-AG12),"") -> 0 | AL12: =IFERROR((AK12-AJ12),"") -> 0 | AO12: =IFERROR((AN12-AM12),"") -> 0 | AR12: =IFERROR((AQ12-AP12),"") -> 0
A13: 3 | B13: CORN | C13: 1 | D13: 30 | E13: 60 | F13: 0.91666667 | G13: 1.2083333 | H13: =HOUR(G13-F13)+MINUTE(G13-F13)/60 -> 7 | I13: 1.2083333 | J13: 1.25 | K13: =HOUR(J13-I13)+MINUTE(J13-I13)/60 -> 1 | M13: 153 | N13: 1 | Q13: 3.Loại Lưới : | R13: 3,0mm | S13: 0.95833333 | V13: 40.02 | W13: 12.5 | X13: 33 | Y13: thanh | Z13: 123 | AA13: 68 | AB13: 100 | AC13: 101 | AD13: 118 | AE13: 32 | AG13: 40972 | AH13: 41544 | AI13: =IFERROR((AH13-AG13),"") -> 572 | AJ13: 9208292 | AK13: 9208395 | AL13: =IFERROR((AK13-AJ13),"") -> 103 | AM13: 958409 | AN13: 958608 | AO13: =IFERROR((AN13-AM13),"") -> 199 | AP13: 366708 | AQ13: 367080 | AR13: =IFERROR((AQ13-AP13),"") -> 372
H14: =HOUR(G14-F14)+MINUTE(G14-F14)/60 -> 0 | K14: =HOUR(J14-I14)+MINUTE(J14-I14)/60 -> 0 | S14: 1 | V14: 41.03 | W14: 12.5 | X14: 33 | Y14: thanh | Z14: 120 | AA14: 70 | AB14: 100 | AC14: 101 | AD14: 118 | AE14: 31 | AI14: =IFERROR((AH14-AG14),"") -> 0 | AL14: =IFERROR((AK14-AJ14),"") -> 0 | AO14: =IFERROR((AN14-AM14),"") -> 0 | AR14: =IFERROR((AQ14-AP14),"") -> 0
H15: =HOUR(G15-F15)+MINUTE(G15-F15)/60 -> 0 | K15: =HOUR(J15-I15)+MINUTE(J15-I15)/60 -> 0 | S15: 1.0416667 | V15: 40.21 | W15: 12.5 | X15: 34 | Y15: thanh | Z15: 125 | AA15: 68 | AB15: 100 | AC15: 101 | AD15: 119 | AE15: 31 | AI15: =IFERROR((AH15-AG15),"") -> 0 | AL15: =IFERROR((AK15-AJ15),"") -> 0 | AO15: =IFERROR((AN15-AM15),"") -> 0 | AR15: =IFERROR((AQ15-AP15),"") -> 0
H16: =HOUR(G16-F16)+MINUTE(G16-F16)/60 -> 0 | K16: =HOUR(J16-I16)+MINUTE(J16-I16)/60 -> 0 | S16: 1.0833333 | V16: 40.03 | W16: 12.5 | X16: 34 | Y16: thanh | Z16: 119 | AA16: 68 | AB16: 100 | AC16: 102 | AD16: 120 | AE16: 30 | AI16: =IFERROR((AH16-AG16),"") -> 0 | AL16: =IFERROR((AK16-AJ16),"") -> 0 | AO16: =IFERROR((AN16-AM16),"") -> 0 | AR16: =IFERROR((AQ16-AP16),"") -> 0
H17: =HOUR(G17-F17)+MINUTE(G17-F17)/60 -> 0 | K17: =HOUR(J17-I17)+MINUTE(J17-I17)/60 -> 0 | S17: 1.125 | V17: 40.12 | W17: 12.5 | X17: 33 | Y17: thanh | Z17: 132 | AA17: 68 | AB17: 100 | AC17: 100 | AD17: 120 | AE17: 30 | AI17: =IFERROR((AH17-AG17),"") -> 0 | AL17: =IFERROR((AK17-AJ17),"") -> 0 | AO17: =IFERROR((AN17-AM17),"") -> 0 | AR17: =IFERROR((AQ17-AP17),"") -> 0
H18: =HOUR(G18-F18)+MINUTE(G18-F18)/60 -> 0 | K18: =HOUR(J18-I18)+MINUTE(J18-I18)/60 -> 0 | S18: 1.1666667 | V18: 40.11 | W18: 12.5 | X18: 34 | Y18: thanh | Z18: 116 | AA18: 70 | AB18: 100 | AC18: 101 | AD18: 119 | AE18: 30 | AI18: =IFERROR((AH18-AG18),"") -> 0 | AL18: =IFERROR((AK18-AJ18),"") -> 0 | AO18: =IFERROR((AN18-AM18),"") -> 0 | AR18: =IFERROR((AQ18-AP18),"") -> 0
H19: =HOUR(G19-F19)+MINUTE(G19-F19)/60 -> 0 | K19: =HOUR(J19-I19)+MINUTE(J19-I19)/60 -> 0 | S19: 1.2083333 | V19: 40.15 | W19: 12.5 | X19: 34 | Y19: thanh | Z19: 121 | AA19: 70 | AB19: 100 | AC19: 101 | AD19: 119 | AE19: 30 | AI19: =IFERROR((AH19-AG19),"") -> 0 | AL19: =IFERROR((AK19-AJ19),"") -> 0 | AO19: =IFERROR((AN19-AM19),"") -> 0 | AR19: =IFERROR((AQ19-AP19),"") -> 0
